Workbook

Sheet data_LabourForce
A1: year | B1: Y | C1: C | D1: I | E1: G | F1: T | G1: D_GDP | H1: D_C | I1: POP | J1: LS | K1: E | L1: U | M1: W | N1: H | O1: P | P1: r | Q1: TT
A2: 1995 | B2: =IF(HLOOKUP(B$1,集計加工用!$B$1:$AL$47,ROW(),FALSE)=0,"NA",HLOOKUP(B$1,集計加工用!$B$1:$AL$47,ROW(),FALSE)) -> 530463.2 | C2: =IF(HLOOKUP(C$1,集計加工用!$B$1:$AL$47,ROW(),FALSE)=0,"NA",HLOOKUP(C$1,集計加工用!$B$1:$AL$47,ROW(),FALSE)) -> 274056.6 | D2: =IF(HLOOKUP(D$1,集計加工用!$B$1:$AL$47,ROW(),FALSE)=0,"NA",HLOOKUP(D$1,集計加工用!$B$1:$AL$47,ROW(),FALSE)) -> 125366.8 | E2: =IF(HLOOKUP(E$1,集計加工用!$B$1:$AL$47,ROW(),FALSE)=0,"NA",HLOOKUP(E$1,集計加工用!$B$1:$AL$47,ROW(),FALSE)) -> 124557.1 | F2: =IF(HLOOKUP(F$1,集計加工用!$B$1:$AL$47,ROW(),FALSE)=0,"NA",HLOOKUP(F$1,集計加工用!$B$1:$AL$47,ROW(),FALSE)) -> 114170.1 | G2: =IF(HLOOKUP(G$1,集計加工用!$B$1:$AL$47,ROW(),FALSE)=0,"NA",HLOOKUP(G$1,集計加工用!$B$1:$AL$47,ROW(),FALSE)) -> 111.6 | H2: =IF(HLOOKUP(H$1,集計加工用!$B$1:$AL$47,ROW(),FALSE)=0,"NA",HLOOKUP(H$1,集計加工用!$B$1:$AL$47,ROW(),FALSE)) -> 105.2 | I2: =IF(HLOOKUP(I$1,集計加工用!$B$1:$AL$47,ROW(),FALSE)=0,"NA",HLOOKUP(I$1,集計加工用!$B$1:$AL$47,ROW(),FALSE)) -> 105556 | ... Q2: =IF(HLOOKUP(Q$1,集計加工用!$B$1:$AL$47,ROW(),FALSE)=0,"NA",HLOOKUP(Q$1,集計加工用!$B$1:$AL$47,ROW(),FALSE)) -> 1.7517662
A3: 1996 | B3: =IF(HLOOKUP(B$1,集計加工用!$B$1:$AL$47,ROW(),FALSE)=0,"NA",HLOOKUP(B$1,集計加工用!$B$1:$AL$47,ROW(),FALSE)) -> 546227.9 | C3: =IF(HLOOKUP(C$1,集計加工用!$B$1:$AL$47,ROW(),FALSE)=0,"NA",HLOOKUP(C$1,集計加工用!$B$1:$AL$47,ROW(),FALSE)) -> 279898 | D3: =IF(HLOOKUP(D$1,集計加工用!$B$1:$AL$47,ROW(),FALSE)=0,"NA",HLOOKUP(D$1,集計加工用!$B$1:$AL$47,ROW(),FALSE)) -> 134570.9 | E3: =IF(HLOOKUP(E$1,集計加工用!$B$1:$AL$47,ROW(),FALSE)=0,"NA",HLOOKUP(E$1,集計加工用!$B$1:$AL$47,ROW(),FALSE)) -> 129736.7 | F3: =IF(HLOOKUP(F$1,集計加工用!$B$1:$AL$47,ROW(),FALSE)=0,"NA",HLOOKUP(F$1,集計加工用!$B$1:$AL$47,ROW(),FALSE)) -> 115264.8 | G3: =IF(HLOOKUP(G$1,集計加工用!$B$1:$AL$47,ROW(),FALSE)=0,"NA",HLOOKUP(G$1,集計加工用!$B$1:$AL$47,ROW(),FALSE)) -> 111.5 | H3: =IF(HLOOKUP(H$1,集計加工用!$B$1:$AL$47,ROW(),FALSE)=0,"NA",HLOOKUP(H$1,集計加工用!$B$1:$AL$47,ROW(),FALSE)) -> 105.4 | I3: =IF(HLOOKUP(I$1,集計加工用!$B$1:$AL$47,ROW(),FALSE)=0,"NA",HLOOKUP(I$1,集計加工用!$B$1:$AL$47,ROW(),FALSE)) -> 106173 | ... Q3: =IF(HLOOKUP(Q$1,集計加工用!$B$1:$AL$47,ROW(),FALSE)=0,"NA",HLOOKUP(Q$1,集計加工用!$B$1:$AL$47,ROW(),FALSE)) -> 1.5187823
A4: 1997 | B4: =IF(HLOOKUP(B$1,集計加工用!$B$1:$AL$47,ROW(),FALSE)=0,"NA",HLOOKUP(B$1,集計加工用!$B$1:$AL$47,ROW(),FALSE)) -> 554111.8 | C4: =IF(HLOOKUP(C$1,集計加工用!$B$1:$AL$47,ROW(),FALSE)=0,"NA",HLOOKUP(C$1,集計加工用!$B$1:$AL$47,ROW(),FALSE)) -> 284813.7 | D4: =IF(HLOOKUP(D$1,集計加工用!$B$1:$AL$47,ROW(),FALSE)=0,"NA",HLOOKUP(D$1,集計加工用!$B$1:$AL$47,ROW(),FALSE)) -> 135287 | E4: =IF(HLOOKUP(E$1,集計加工用!$B$1:$AL$47,ROW(),FALSE)=0,"NA",HLOOKUP(E$1,集計加工用!$B$1:$AL$47,ROW(),FALSE)) -> 128663.4 | F4: =IF(HLOOKUP(F$1,集計加工用!$B$1:$AL$47,ROW(),FALSE)=0,"NA",HLOOKUP(F$1,集計加工用!$B$1:$AL$47,ROW(),FALSE)) -> 126647.3 | G4: =IF(HLOOKUP(G$1,集計加工用!$B$1:$AL$47,ROW(),FALSE)=0,"NA",HLOOKUP(G$1,集計加工用!$B$1:$AL$47,ROW(),FALSE)) -> 111.6 | H4: =IF(HLOOKUP(H$1,集計加工用!$B$1:$AL$47,ROW(),FALSE)=0,"NA",HLOOKUP(H$1,集計加工用!$B$1:$AL$47,ROW(),FALSE)) -> 106.7 | I4: =IF(HLOOKUP(I$1,集計加工用!$B$1:$AL$47,ROW(),FALSE)=0,"NA",HLOOKUP(I$1,集計加工用!$B$1:$AL$47,ROW(),FALSE)) -> 106791 | ... Q4: =IF(HLOOKUP(Q$1,集計加工用!$B$1:$AL$47,ROW(),FALSE)=0,"NA",HLOOKUP(Q$1,集計加工用!$B$1:$AL$47,ROW(),FALSE)) -> 1.3500091
A5: 1998 | B5: =IF(HLOOKUP(B$1,集計加工用!$B$1:$AL$47,ROW(),FALSE)=0,"NA",HLOOKUP(B$1,集計加工用!$B$1:$AL$47,ROW(),FALSE)) -> 543304 | C5: =IF(HLOOKUP(C$1,集計加工用!$B$1:$AL$47,ROW(),FALSE)=0,"NA",HLOOKUP(C$1,集計加工用!$B$1:$AL$47,ROW(),FALSE)) -> 283238.3 | D5: =IF(HLOOKUP(D$1,集計加工用!$B$1:$AL$47,ROW(),FALSE)=0,"NA",HLOOKUP(D$1,集計加工用!$B$1:$AL$47,ROW(),FALSE)) -> 123964 | E5: =IF(HLOOKUP(E$1,集計加工用!$B$1:$AL$47,ROW(),FALSE)=0,"NA",HLOOKUP(E$1,集計加工用!$B$1:$AL$47,ROW(),FALSE)) -> 126742.9 | F5: =IF(HLOOKUP(F$1,集計加工用!$B$1:$AL$47,ROW(),FALSE)=0,"NA",HLOOKUP(F$1,集計加工用!$B$1:$AL$47,ROW(),FALSE)) -> 129640.5 | G5: =IF(HLOOKUP(G$1,集計加工用!$B$1:$AL$47,ROW(),FALSE)=0,"NA",HLOOKUP(G$1,集計加工用!$B$1:$AL$47,ROW(),FALSE)) -> 111.4 | H5: =IF(HLOOKUP(H$1,集計加工用!$B$1:$AL$47,ROW(),FALSE)=0,"NA",HLOOKUP(H$1,集計加工用!$B$1:$AL$47,ROW(),FALSE)) -> 106.8 | I5: =IF(HLOOKUP(I$1,集計加工用!$B$1:$AL$47,ROW(),FALSE)=0,"NA",HLOOKUP(I$1,集計加工用!$B$1:$AL$47,ROW(),FALSE)) -> 107413 | ... Q5: =IF(HLOOKUP(Q$1,集計加工用!$B$1:$AL$47,ROW(),FALSE)=0,"NA",HLOOKUP(Q$1,集計加工用!$B$1:$AL$47,ROW(),FALSE)) -> 1.3670198
A6: 1999 | B6: =IF(HLOOKUP(B$1,集計加工用!$B$1:$AL$47,ROW(),FALSE)=0,"NA",HLOOKUP(B$1,集計加工用!$B$1:$AL$47,ROW(),FALSE)) -> 534107.1 | C6: =IF(HLOOKUP(C$1,集計加工用!$B$1:$AL$47,ROW(),FALSE)=0,"NA",HLOOKUP(C$1,集計加工用!$B$1:$AL$47,ROW(),FALSE)) -> 284604.1 | D6: =IF(HLOOKUP(D$1,集計加工用!$B$1:$AL$47,ROW(),FALSE)=0,"NA",HLOOKUP(D$1,集計加工用!$B$1:$AL$47,ROW(),FALSE)) -> 111656.6 | E6: =IF(HLOOKUP(E$1,集計加工用!$B$1:$AL$47,ROW(),FALSE)=0,"NA",HLOOKUP(E$1,集計加工用!$B$1:$AL$47,ROW(),FALSE)) -> 130002.3 | F6: =IF(HLOOKUP(F$1,集計加工用!$B$1:$AL$47,ROW(),FALSE)=0,"NA",HLOOKUP(F$1,集計加工用!$B$1:$AL$47,ROW(),FALSE)) -> 122474.1 | G6: =IF(HLOOKUP(G$1,集計加工用!$B$1:$AL$47,ROW(),FALSE)=0,"NA",HLOOKUP(G$1,集計加工用!$B$1:$AL$47,ROW(),FALSE)) -> 109.9 | H6: =IF(HLOOKUP(H$1,集計加工用!$B$1:$AL$47,ROW(),FALSE)=0,"NA",HLOOKUP(H$1,集計加工用!$B$1:$AL$47,ROW(),FALSE)) -> 106.1 | I6: =IF(HLOOKUP(I$1,集計加工用!$B$1:$AL$47,ROW(),FALSE)=0,"NA",HLOOKUP(I$1,集計加工用!$B$1:$AL$47,ROW(),FALSE)) -> 107925 | ... Q6: =IF(HLOOKUP(Q$1,集計加工用!$B$1:$AL$47,ROW(),FALSE)=0,"NA",HLOOKUP(Q$1,集計加工用!$B$1:$AL$47,ROW(),FALSE)) -> 1.4851131
A7: 2000 | B7: =IF(HLOOKUP(B$1,集計加工用!$B$1:$AL$47,ROW(),FALSE)=0,"NA",HLOOKUP(B$1,集計加工用!$B$1:$AL$47,ROW(),FALSE)) -> 543394.8 | C7: =IF(HLOOKUP(C$1,集計加工用!$B$1:$AL$47,ROW(),FALSE)=0,"NA",HLOOKUP(C$1,集計加工用!$B$1:$AL$47,ROW(),FALSE)) -> 286394.8 | D7: =IF(HLOOKUP(D$1,集計加工用!$B$1:$AL$47,ROW(),FALSE)=0,"NA",HLOOKUP(D$1,集計加工用!$B$1:$AL$47,ROW(),FALSE)) -> 120845.6 | E7: =IF(HLOOKUP(E$1,集計加工用!$B$1:$AL$47,ROW(),FALSE)=0,"NA",HLOOKUP(E$1,集計加工用!$B$1:$AL$47,ROW(),FALSE)) -> 128848 | F7: =IF(HLOOKUP(F$1,集計加工用!$B$1:$AL$47,ROW(),FALSE)=0,"NA",HLOOKUP(F$1,集計加工用!$B$1:$AL$47,ROW(),FALSE)) -> 117304 | G7: =IF(HLOOKUP(G$1,集計加工用!$B$1:$AL$47,ROW(),FALSE)=0,"NA",HLOOKUP(G$1,集計加工用!$B$1:$AL$47,ROW(),FALSE)) -> 108.6 | H7: =IF(HLOOKUP(H$1,集計加工用!$B$1:$AL$47,ROW(),FALSE)=0,"NA",HLOOKUP(H$1,集計加工用!$B$1:$AL$47,ROW(),FALSE)) -> 105.1 | I7: =IF(HLOOKUP(I$1,集計加工用!$B$1:$AL$47,ROW(),FALSE)=0,"NA",HLOOKUP(I$1,集計加工用!$B$1:$AL$47,ROW(),FALSE)) -> 108454 | ... Q7: =IF(HLOOKUP(Q$1,集計加工用!$B$1:$AL$47,ROW(),FALSE)=0,"NA",HLOOKUP(Q$1,集計加工用!$B$1:$AL$47,ROW(),FALSE)) -> 1.4311401
A8: 2001 | B8: =IF(HLOOKUP(B$1,集計加工用!$B$1:$AL$47,ROW(),FALSE)=0,"NA",HLOOKUP(B$1,集計加工用!$B$1:$AL$47,ROW(),FALSE)) -> 539441.6 | C8: =IF(HLOOKUP(C$1,集計加工用!$B$1:$AL$47,ROW(),FALSE)=0,"NA",HLOOKUP(C$1,集計加工用!$B$1:$AL$47,ROW(),FALSE)) -> 288170.9 | D8: =IF(HLOOKUP(D$1,集計加工用!$B$1:$AL$47,ROW(),FALSE)=0,"NA",HLOOKUP(D$1,集計加工用!$B$1:$AL$47,ROW(),FALSE)) -> 118323.6 | E8: =IF(HLOOKUP(E$1,集計加工用!$B$1:$AL$47,ROW(),FALSE)=0,"NA",HLOOKUP(E$1,集計加工用!$B$1:$AL$47,ROW(),FALSE)) -> 129789.2 | F8: =IF(HLOOKUP(F$1,集計加工用!$B$1:$AL$47,ROW(),FALSE)=0,"NA",HLOOKUP(F$1,集計加工用!$B$1:$AL$47,ROW(),FALSE)) -> 126951.6 | G8: =IF(HLOOKUP(G$1,集計加工用!$B$1:$AL$47,ROW(),FALSE)=0,"NA",HLOOKUP(G$1,集計加工用!$B$1:$AL$47,ROW(),FALSE)) -> 107.5 | H8: =IF(HLOOKUP(H$1,集計加工用!$B$1:$AL$47,ROW(),FALSE)=0,"NA",HLOOKUP(H$1,集計加工用!$B$1:$AL$47,ROW(),FALSE)) -> 103.7 | I8: =IF(HLOOKUP(I$1,集計加工用!$B$1:$AL$47,ROW(),FALSE)=0,"NA",HLOOKUP(I$1,集計加工用!$B$1:$AL$47,ROW(),FALSE)) -> 109033 | ... Q8: =IF(HLOOKUP(Q$1,集計加工用!$B$1:$AL$47,ROW(),FALSE)=0,"NA",HLOOKUP(Q$1,集計加工用!$B$1:$AL$47,ROW(),FALSE)) -> 1.3308492
A9: 2002 | B9: =IF(HLOOKUP(B$1,集計加工用!$B$1:$AL$47,ROW(),FALSE)=0,"NA",HLOOKUP(B$1,集計加工用!$B$1:$AL$47,ROW(),FALSE)) -> 532390.8 | C9: =IF(HLOOKUP(C$1,集計加工用!$B$1:$AL$47,ROW(),FALSE)=0,"NA",HLOOKUP(C$1,集計加工用!$B$1:$AL$47,ROW(),FALSE)) -> 287665.9 | D9: =IF(HLOOKUP(D$1,集計加工用!$B$1:$AL$47,ROW(),FALSE)=0,"NA",HLOOKUP(D$1,集計加工用!$B$1:$AL$47,ROW(),FALSE)) -> 108975.2 | E9: =IF(HLOOKUP(E$1,集計加工用!$B$1:$AL$47,ROW(),FALSE)=0,"NA",HLOOKUP(E$1,集計加工用!$B$1:$AL$47,ROW(),FALSE)) -> 129121.4 | F9: =IF(HLOOKUP(F$1,集計加工用!$B$1:$AL$47,ROW(),FALSE)=0,"NA",HLOOKUP(F$1,集計加工用!$B$1:$AL$47,ROW(),FALSE)) -> 124845.7 | G9: =IF(HLOOKUP(G$1,集計加工用!$B$1:$AL$47,ROW(),FALSE)=0,"NA",HLOOKUP(G$1,集計加工用!$B$1:$AL$47,ROW(),FALSE)) -> 106 | H9: =IF(HLOOKUP(H$1,集計加工用!$B$1:$AL$47,ROW(),FALSE)=0,"NA",HLOOKUP(H$1,集計加工用!$B$1:$AL$47,ROW(),FALSE)) -> 102.2 | I9: =IF(HLOOKUP(I$1,集計加工用!$B$1:$AL$47,ROW(),FALSE)=0,"NA",HLOOKUP(I$1,集計加工用!$B$1:$AL$47,ROW(),FALSE)) -> 109384 | ... Q9: =IF(HLOOKUP(Q$1,集計加工用!$B$1:$AL$47,ROW(),FALSE)=0,"NA",HLOOKUP(Q$1,集計加工用!$B$1:$AL$47,ROW(),FALSE)) -> 1.2982596
A10: 2003 | B10: =IF(HLOOKUP(B$1,集計加工用!$B$1:$AL$47,ROW(),FALSE)=0,"NA",HLOOKUP(B$1,集計加工用!$B$1:$AL$47,ROW(),FALSE)) -> 530211.8 | C10: =IF(HLOOKUP(C$1,集計加工用!$B$1:$AL$47,ROW(),FALSE)=0,"NA",HLOOKUP(C$1,集計加工用!$B$1:$AL$47,ROW(),FALSE)) -> 286411.7 | D10: =IF(HLOOKUP(D$1,集計加工用!$B$1:$AL$47,ROW(),FALSE)=0,"NA",HLOOKUP(D$1,集計加工用!$B$1:$AL$47,ROW(),FALSE)) -> 108871 | E10: =IF(HLOOKUP(E$1,集計加工用!$B$1:$AL$47,ROW(),FALSE)=0,"NA",HLOOKUP(E$1,集計加工用!$B$1:$AL$47,ROW(),FALSE)) -> 126516.9 | F10: =IF(HLOOKUP(F$1,集計加工用!$B$1:$AL$47,ROW(),FALSE)=0,"NA",HLOOKUP(F$1,集計加工用!$B$1:$AL$47,ROW(),FALSE)) -> 117683 | G10: =IF(HLOOKUP(G$1,集計加工用!$B$1:$AL$47,ROW(),FALSE)=0,"NA",HLOOKUP(G$1,集計加工用!$B$1:$AL$47,ROW(),FALSE)) -> 104.1 | H10: =IF(HLOOKUP(H$1,集計加工用!$B$1:$AL$47,ROW(),FALSE)=0,"NA",HLOOKUP(H$1,集計加工用!$B$1:$AL$47,ROW(),FALSE)) -> 101.1 | I10: =IF(HLOOKUP(I$1,集計加工用!$B$1:$AL$47,ROW(),FALSE)=0,"NA",HLOOKUP(I$1,集計加工用!$B$1:$AL$47,ROW(),FALSE)) -> 109789 | ... Q10: =IF(HLOOKUP(Q$1,集計加工用!$B$1:$AL$47,ROW(),FALSE)=0,"NA",HLOOKUP(Q$1,集計加工用!$B$1:$AL$47,ROW(),FALSE)) -> 1.2955047
A11: 2004 | B11: =IF(HLOOKUP(B$1,集計加工用!$B$1:$AL$47,ROW(),FALSE)=0,"NA",HLOOKUP(B$1,集計加工用!$B$1:$AL$47,ROW(),FALSE)) -> 534634.1 | C11: =IF(HLOOKUP(C$1,集計加工用!$B$1:$AL$47,ROW(),FALSE)=0,"NA",HLOOKUP(C$1,集計加工用!$B$1:$AL$47,ROW(),FALSE)) -> 288414.1 | D11: =IF(HLOOKUP(D$1,集計加工用!$B$1:$AL$47,ROW(),FALSE)=0,"NA",HLOOKUP(D$1,集計加工用!$B$1:$AL$47,ROW(),FALSE)) -> 112132.4 | E11: =IF(HLOOKUP(E$1,集計加工用!$B$1:$AL$47,ROW(),FALSE)=0,"NA",HLOOKUP(E$1,集計加工用!$B$1:$AL$47,ROW(),FALSE)) -> 123987.4 | F11: =IF(HLOOKUP(F$1,集計加工用!$B$1:$AL$47,ROW(),FALSE)=0,"NA",HLOOKUP(F$1,集計加工用!$B$1:$AL$47,ROW(),FALSE)) -> 115591.6 | G11: =IF(HLOOKUP(G$1,集計加工用!$B$1:$AL$47,ROW(),FALSE)=0,"NA",HLOOKUP(G$1,集計加工用!$B$1:$AL$47,ROW(),FALSE)) -> 102.8 | H11: =IF(HLOOKUP(H$1,集計加工用!$B$1:$AL$47,ROW(),FALSE)=0,"NA",HLOOKUP(H$1,集計加工用!$B$1:$AL$47,ROW(),FALSE)) -> 100.6 | I11: =IF(HLOOKUP(I$1,集計加工用!$B$1:$AL$47,ROW(),FALSE)=0,"NA",HLOOKUP(I$1,集計加工用!$B$1:$AL$47,ROW(),FALSE)) -> 110053 | ... Q11: =IF(HLOOKUP(Q$1,集計加工用!$B$1:$AL$47,ROW(),FALSE)=0,"NA",HLOOKUP(Q$1,集計加工用!$B$1:$AL$47,ROW(),FALSE)) -> 1.2689974
A12: 2005 | B12: =IF(HLOOKUP(B$1,集計加工用!$B$1:$AL$47,ROW(),FALSE)=0,"NA",HLOOKUP(B$1,集計加工用!$B$1:$AL$47,ROW(),FALSE)) -> 537385.2 | C12: =IF(HLOOKUP(C$1,集計加工用!$B$1:$AL$47,ROW(),FALSE)=0,"NA",HLOOKUP(C$1,集計加工用!$B$1:$AL$47,ROW(),FALSE)) -> 290679.3 | D12: =IF(HLOOKUP(D$1,集計加工用!$B$1:$AL$47,ROW(),FALSE)=0,"NA",HLOOKUP(D$1,集計加工用!$B$1:$AL$47,ROW(),FALSE)) -> 116899.6 | E12: =IF(HLOOKUP(E$1,集計加工用!$B$1:$AL$47,ROW(),FALSE)=0,"NA",HLOOKUP(E$1,集計加工用!$B$1:$AL$47,ROW(),FALSE)) -> 122348.6 | F12: =IF(HLOOKUP(F$1,集計加工用!$B$1:$AL$47,ROW(),FALSE)=0,"NA",HLOOKUP(F$1,集計加工用!$B$1:$AL$47,ROW(),FALSE)) -> 119292.2 | G12: =IF(HLOOKUP(G$1,集計加工用!$B$1:$AL$47,ROW(),FALSE)=0,"NA",HLOOKUP(G$1,集計加工用!$B$1:$AL$47,ROW(),FALSE)) -> 101.5 | H12: =IF(HLOOKUP(H$1,集計加工用!$B$1:$AL$47,ROW(),FALSE)=0,"NA",HLOOKUP(H$1,集計加工用!$B$1:$AL$47,ROW(),FALSE)) -> 99.7 | I12: =IF(HLOOKUP(I$1,集計加工用!$B$1:$AL$47,ROW(),FALSE)=0,"NA",HLOOKUP(I$1,集計加工用!$B$1:$AL$47,ROW(),FALSE)) -> 110247 | ... Q12: =IF(HLOOKUP(Q$1,集計加工用!$B$1:$AL$47,ROW(),FALSE)=0,"NA",HLOOKUP(Q$1,集計加工用!$B$1:$AL$47,ROW(),FALSE)) -> 1.130994
A13: 2006 | B13: =IF(HLOOKUP(B$1,集計加工用!$B$1:$AL$47,ROW(),FALSE)=0,"NA",HLOOKUP(B$1,集計加工用!$B$1:$AL$47,ROW(),FALSE)) -> 540566 | C13: =IF(HLOOKUP(C$1,集計加工用!$B$1:$AL$47,ROW(),FALSE)=0,"NA",HLOOKUP(C$1,集計加工用!$B$1:$AL$47,ROW(),FALSE)) -> 293508.6 | D13: =IF(HLOOKUP(D$1,集計加工用!$B$1:$AL$47,ROW(),FALSE)=0,"NA",HLOOKUP(D$1,集計加工用!$B$1:$AL$47,ROW(),FALSE)) -> 119256.3 | E13: =IF(HLOOKUP(E$1,集計加工用!$B$1:$AL$47,ROW(),FALSE)=0,"NA",HLOOKUP(E$1,集計加工用!$B$1:$AL$47,ROW(),FALSE)) -> 120862.9 | F13: =IF(HLOOKUP(F$1,集計加工用!$B$1:$AL$47,ROW(),FALSE)=0,"NA",HLOOKUP(F$1,集計加工用!$B$1:$AL$47,ROW(),FALSE)) -> 115174.4 | G13: =IF(HLOOKUP(G$1,集計加工用!$B$1:$AL$47,ROW(),FALSE)=0,"NA",HLOOKUP(G$1,集計加工用!$B$1:$AL$47,ROW(),FALSE)) -> 100.5 | H13: =IF(HLOOKUP(H$1,集計加工用!$B$1:$AL$47,ROW(),FALSE)=0,"NA",HLOOKUP(H$1,集計加工用!$B$1:$AL$47,ROW(),FALSE)) -> 99.7 | I13: =IF(HLOOKUP(I$1,集計加工用!$B$1:$AL$47,ROW(),FALSE)=0,"NA",HLOOKUP(I$1,集計加工用!$B$1:$AL$47,ROW(),FALSE)) -> 110466 | ... Q13: =IF(HLOOKUP(Q$1,集計加工用!$B$1:$AL$47,ROW(),FALSE)=0,"NA",HLOOKUP(Q$1,集計加工用!$B$1:$AL$47,ROW(),FALSE)) -> 0.98504561
... A47: 2040 | B47: =IF(HLOOKUP(B$1,集計加工用!$B$1:$AL$47,ROW(),FALSE)=0,"NA",HLOOKUP(B$1,集計加工用!$B$1:$AL$47,ROW(),FALSE)) -> 806846.72 | C47: =IF(HLOOKUP(C$1,集計加工用!$B$1:$AL$47,ROW(),FALSE)=0,"NA",HLOOKUP(C$1,集計加工用!$B$1:$AL$47,ROW(),FALSE)) -> 427381.55 | D47: =IF(HLOOKUP(D$1,集計加工用!$B$1:$AL$47,ROW(),FALSE)=0,"NA",HLOOKUP(D$1,集計加工用!$B$1:$AL$47,ROW(),FALSE)) -> 184269 | E47: =IF(HLOOKUP(E$1,集計加工用!$B$1:$AL$47,ROW(),FALSE)=0,"NA",HLOOKUP(E$1,集計加工用!$B$1:$AL$47,ROW(),FALSE)) -> NA | F47: =IF(HLOOKUP(F$1,集計加工用!$B$1:$AL$47,ROW(),FALSE)=0,"NA",HLOOKUP(F$1,集計加工用!$B$1:$AL$47,ROW(),FALSE)) -> NA | G47: =IF(HLOOKUP(G$1,集計加工用!$B$1:$AL$47,ROW(),FALSE)=0,"NA",HLOOKUP(G$1,集計加工用!$B$1:$AL$47,ROW(),FALSE)) -> 126.68561 | H47: =IF(HLOOKUP(H$1,集計加工用!$B$1:$AL$47,ROW(),FALSE)=0,"NA",HLOOKUP(H$1,集計加工用!$B$1:$AL$47,ROW(),FALSE)) -> 128.60509 | I47: =IF(HLOOKUP(I$1,集計加工用!$B$1:$AL$47,ROW(),FALSE)=0,"NA",HLOOKUP(I$1,集計加工用!$B$1:$AL$47,ROW(),FALSE)) -> 101418 | ... Q47: =IF(HLOOKUP(Q$1,集計加工用!$B$1:$AL$47,ROW(),FALSE)=0,"NA",HLOOKUP(Q$1,集計加工用!$B$1:$AL$47,ROW(),FALSE)) -> 0.71206144

Sheet 集計加工用
A1: year | B1: Y | C1: Y/総人口 | D1: ΔY/総人口 | E1: Y_prj | F1: C | G1: I | H1: I_hus | I1: I_fac | J1: I_inv | K1: G | L1: G_c | M1: G_k | N1: G_inv | O1: T | P1: 可処分所得 | Q1: D_GDP | R1: D_GDP（増減率） | S1: D_C | T1: POP | U1: 総人口 | V1: ～14歳 | W1: LS | X1: E | Y1: U | Z1: W | AA1: WM | AB1: WM_org | AC1: WM_inc | AD1: H | AE1: H_org | AF1: H_inc | AG1: P | AH1: P（増減率） | AI1: r | AJ1: EXP_外貨建 | AK1: IMP_円建 | AL1: TT | AM1: Trend
A2: 1995 | B2: 530463.2 | C2: =B2/U2 -> 4.2244421 | F2: 274056.6 | G2: =SUM(H2:J2) -> 125366.8 | H2: 31878.2 | I2: 91924.2 | J2: 1564.4 | K2: =SUM(L2:N2) -> 124557.1 | L2: 78549.9 | M2: 45895 | N2: 112.2 | O2: =B2-P2 -> 114170.1 | P2: 416293.1 | Q2: 111.6 | S2: 105.2 | T2: =U2-V2 -> 105556 | U2: 125570 | V2: 20014 | W2: 6666 | X2: 6457 | Y2: 210 | Z2: =AA2/AD2*100 -> 93.293718 | AA2: =AB2 -> 109.9 | AB2: 109.9 | AC2: 1.1 | AD2: =AE2 -> 117.8 | AE2: 117.8 | AF2: 0.1 | AG2: 95.9 | AI2: 3.5058333 | AJ2: 136.375 | AK2: 77.85 | AL2: =AJ2/AK2 -> 1.7517662 | AM2: 1
A3: 1996 | B3: 546227.9 | C3: =B3/U3 -> 4.3399987 | D3: =C3/C2 -> 1.0273543 | F3: 279898 | G3: =SUM(H3:J3) -> 134570.9 | H3: 35343.6 | I3: 96951.9 | J3: 2275.4 | K3: =SUM(L3:N3) -> 129736.7 | L3: 81158.7 | M3: 48325.3 | N3: 252.7 | O3: =B3-P3 -> 115264.8 | P3: 430963.1 | Q3: 111.5 | R3: =(Q3/Q2-1)*100 -> -0.089605735 | S3: 105.4 | T3: =U3-V3 -> 106173 | U3: 125859 | V3: 19686 | W3: 6711 | X3: 6486 | Y3: 225 | Z3: =AA3/AD3*100 -> 94.2324 | AA3: =AB3 -> 111.1 | AB3: 111.1 | AC3: 1.1 | AD3: =AE3 -> 117.9 | AE3: 117.9 | AF3: 0.1 | AG3: 96 | AH3: =(AG3/AG2-1)*100 -> 0.10427529 | AI3: 2.6575833 | AJ3: 129.71667 | AK3: 85.408333 | AL3: =AJ3/AK3 -> 1.5187823 | AM3: 2
A4: 1997 | B4: 554111.8 | C4: =B4/U4 -> 4.3922398 | D4: =C4/C3 -> 1.0120371 | F4: 284813.7 | G4: =SUM(H4:J4) -> 135287 | H4: 32798 | I4: 99717.6 | J4: 2771.4 | K4: =SUM(L4:N4) -> 128663.4 | L4: 83020.6 | M4: 45463.8 | N4: 179 | O4: =B4-P4 -> 126647.3 | P4: 427464.5 | Q4: 111.6 | R4: =(Q4/Q3-1)*100 -> 0.089686099 | S4: 106.7 | T4: =U4-V4 -> 106791 | U4: 126157 | V4: 19366 | W4: 6787 | X4: 6557 | Y4: 230 | Z4: =AA4/AD4*100 -> 97.076526 | AA4: =AB4 -> 112.9 | AB4: 112.9 | AC4: 1.6 | AD4: =AE4 -> 116.3 | AE4: 116.3 | AF4: -1.4 | AG4: 97.7 | AH4: =(AG4/AG3-1)*100 -> 1.7708333 | AI4: 2.4488333 | AJ4: 123.90833 | AK4: 91.783333 | AL4: =AJ4/AK4 -> 1.3500091 | AM4: 3
A5: 1998 | B5: 543304 | C5: =B5/U5 -> 4.2958441 | D5: =C5/C4 -> 0.97805318 | F5: 283238.3 | G5: =SUM(H5:J5) -> 123964 | H5: 27989.8 | I5: 94245.8 | J5: 1728.4 | K5: =SUM(L5:N5) -> 126742.9 | L5: 83865.4 | M5: 42959.7 | N5: -82.2 | O5: =B5-P5 -> 129640.5 | P5: 413663.5 | Q5: 111.4 | R5: =(Q5/Q4-1)*100 -> -0.17921147 | S5: 106.8 | T5: =U5-V5 -> 107413 | U5: 126472 | V5: 19059 | W5: 6793 | X5: 6514 | Y5: 279 | Z5: =AA5/AD5*100 -> 96.869565 | AA5: =AB5 -> 111.4 | AB5: 111.4 | AC5: -1.3 | AD5: =AE5 -> 115 | AE5: 115 | AF5: -1.1 | AG5: 98.3 | AH5: =(AG5/AG4-1)*100 -> 0.61412487 | AI5: 2.3209167 | AJ5: 119.375 | AK5: 87.325 | AL5: =AJ5/AK5 -> 1.3670198 | AM5: 4
A6: 1999 | B6: 534107.1 | C6: =B6/U6 -> 4.2166239 | D6: =C6/C5 -> 0.98155887 | F6: 284604.1 | G6: =SUM(H6:J6) -> 111656.6 | H6: 27625.7 | I6: 87750.6 | J6: -3719.7 | K6: =SUM(L6:N6) -> 130002.3 | L6: 85427.9 | M6: 44694.1 | N6: -119.7 | O6: =B6-P6 -> 122474.1 | P6: 411633 | Q6: 109.9 | R6: =(Q6/Q5-1)*100 -> -1.3464991 | S6: 106.1 | T6: =U6-V6 -> 107925 | U6: 126667 | V6: 18742 | W6: 6779 | X6: 6462 | Y6: 317 | Z6: =AA6/AD6*100 -> 96.48197 | AA6: =AB6 -> 109.7 | AB6: 109.7 | AC6: -1.5 | AD6: =AE6 -> 113.7 | AE6: 113.7 | AF6: -1.2 | AG6: 98 | AH6: =(AG6/AG5-1)*100 -> -0.3051882 | AI6: 2.1608333 | AJ6: 117.63333 | AK6: 79.208333 | AL6: =AJ6/AK6 -> 1.4851131 | AM6: 5
A7: 2000 | B7: 543394.8 | C7: =B7/U7 -> 4.2811938 | D7: =C7/C6 -> 1.0153132 | F7: 286394.8 | G7: =SUM(H7:J7) -> 120845.6 | H7: 28001.5 | I7: 93225.3 | J7: -381.2 | K7: =SUM(L7:N7) -> 128848 | L7: 88567.1 | M7: 40268.9 | N7: 12 | O7: =B7-P7 -> 117304 | P7: 426090.8 | Q7: 108.6 | R7: =(Q7/Q6-1)*100 -> -1.1828935 | S7: 105.1 | T7: =U7-V7 -> 108454 | U7: 126926 | V7: 18472 | W7: 6766 | X7: 6446 | Y7: 320 | Z7: =AA7/AD7*100 -> 95.895197 | AA7: =AB7 -> 109.8 | AB7: 109.8 | AC7: 0.1 | AD7: =AE7 -> 114.5 | AE7: 114.5 | AF7: 0.7 | AG7: 97.3 | AH7: =(AG7/AG6-1)*100 -> -0.71428571 | AI7: 2.0671667 | AJ7: 118.725 | AK7: 82.958333 | AL7: =AJ7/AK7 -> 1.4311401 | AM7: 6
A8: 2001 | B8: 539441.6 | C8: =B8/U8 -> 4.2370291 | D8: =C8/C7 -> 0.98968404 | F8: 288170.9 | G8: =SUM(H8:J8) -> 118323.6 | H8: 27024.8 | I8: 91053.1 | J8: 245.7 | K8: =SUM(L8:N8) -> 129789.2 | L8: 91635.6 | M8: 38254.2 | N8: -100.6 | O8: =B8-P8 -> 126951.6 | P8: 412490 | Q8: 107.5 | R8: =(Q8/Q7-1)*100 -> -1.0128913 | S8: 103.7 | T8: =U8-V8 -> 109033 | U8: 127316 | V8: 18283 | W8: 6752 | X8: 6412 | Y8: 340 | Z8: =AA8/AD8*100 -> 95.410415 | AA8: =AB8 -> 108.1 | AB8: 108.1 | AC8: -1.6 | AD8: =AE8 -> 113.3 | AE8: 113.3 | AF8: -1 | AG8: 96.7 | AH8: =(AG8/AG7-1)*100 -> -0.61664954 | AI8: 1.9694167 | AJ8: 113.1 | AK8: 84.983333 | AL8: =AJ8/AK8 -> 1.3308492 | AM8: 7
A9: 2002 | B9: 532390.8 | C9: =B9/U9 -> 4.1760727 | D9: =C9/C8 -> 0.9856134 | E9: -0.9 | F9: 287665.9 | G9: =SUM(H9:J9) -> 108975.2 | H9: 26127.3 | I9: 84640.2 | J9: -1792.3 | K9: =SUM(L9:N9) -> 129121.4 | L9: 93291.2 | M9: 35913.2 | N9: -83 | O9: =B9-P9 -> 124845.7 | P9: 407545.1 | Q9: 106 | R9: =(Q9/Q8-1)*100 -> -1.3953488 | S9: 102.2 | T9: =U9-V9 -> 109384 | U9: 127486 | V9: 18102 | W9: 6689 | X9: 6330 | Y9: 359 | Z9: =AA9/AD9*100 -> 93.493761 | AA9: =AB9 -> 104.9 | AB9: 104.9 | AC9: -2.9 | AD9: =AE9 -> 112.2 | AE9: 112.2 | AF9: -0.9 | AG9: 95.8 | AH9: =(AG9/AG8-1)*100 -> -0.93071355 | AI9: 1.8649167 | AJ9: 108.78333 | AK9: 83.791667 | AL9: =AJ9/AK9 -> 1.2982596 | AM9: 8
A10: 2003 | B10: 530211.8 | C10: =B10/U10 -> 4.1522061 | D10: =C10/C9 -> 0.99428491 | E10: 0.4 | F10: 286411.7 | G10: =SUM(H10:J10) -> 108871 | H10: 26001.3 | I10: 83039.7 | J10: -170 | K10: =SUM(L10:N10) -> 126516.9 | L10: 93336.1 | M10: 33278.3 | N10: -97.5 | O10: =B10-P10 -> 117683 | P10: 412528.8 | Q10: 104.1 | R10: =(Q10/Q9-1)*100 -> -1.7924528 | S10: 101.1 | T10: =U10-V10 -> 109789 | U10: 127694 | V10: 17905 | W10: 6666 | X10: 6316 | Y10: 350 | Z10: =AA10/AD10*100 -> 92.780749 | AA10: =AB10 -> 104.1 | AB10: 104.1 | AC10: -0.7 | AD10: =AE10 -> 112.2 | AE10: 112.2 | AF10: -0.1 | AG10: 95.5 | AH10: =(AG10/AG9-1)*100 -> -0.3131524 | AI10: 1.8220833 | AJ10: 107.59167 | AK10: 83.05 | AL10: =AJ10/AK10 -> 1.2955047 | AM10: 9
A11: 2004 | B11: 534634.1 | C11: =B11/U11 -> 4.183791 | D11: =C11/C10 -> 1.0076068 | E11: 0.4 | F11: 288414.1 | G11: =SUM(H11:J11) -> 112132.4 | H11: 26870.3 | I11: 83687.1 | J11: 1575 | K11: =SUM(L11:N11) -> 123987.4 | L11: 93570.2 | M11: 30401.7 | N11: 15.5 | O11: =B11-P11 -> 115591.6 | P11: 419042.5 | Q11: 102.8 | R11: =(Q11/Q10-1)*100 -> -1.2487992 | S11: 100.6 | T11: =U11-V11 -> 110053 | U11: 127787 | V11: 17734 | W11: 6642 | X11: 6329 | Y11: 313 | Z11: =AA11/AD11*100 -> 92.170819 | AA11: =AB11 -> 103.6 | AB11: 103.6 | AC11: -0.5 | AD11: =AE11 -> 112.4 | AE11: 112.4 | AF11: 0.1 | AG11: 95.5 | AH11: =(AG11/AG10-1)*100 -> 0 | AI11: 1.7665833 | AJ11: 109.8 | AK11: 86.525 | AL11: =AJ11/AK11 -> 1.2689974 | AM11: 10
A12: 2005 | B12: 537385.2 | C12: =B12/U12 -> 4.2059452 | D12: =C12/C11 -> 1.0052952 | E12: 0.8 | F12: 290679.3 | G12: =SUM(H12:J12) -> 116899.6 | H12: 26941.4 | I12: 89354 | J12: 604.2 | K12: =SUM(L12:N12) -> 122348.6 | L12: 94128.8 | M12: 28160.3 | N12: 59.5 | O12: =B12-P12 -> 119292.2 | P12: 418093 | Q12: 101.5 | R12: =(Q12/Q11-1)*100 -> -1.2645914 | S12: 99.7 | T12: =U12-V12 -> 110247 | U12: 127768 | V12: 17521 | W12: 6651 | X12: 6356 | Y12: 294 | Z12: =AA12/AD12*100 -> 93.375112 | AA12: =AB12 -> 104.3 | AB12: 104.3 | AC12: 0.8 | AD12: =AE12 -> 111.7 | AE12: 111.7 | AF12: -0.6 | AG12: 95.2 | AH12: =(AG12/AG11-1)*100 -> -0.31413613 | AI12: 1.6769167 | AJ12: 110.65833 | AK12: 97.841667 | AL12: =AJ12/AK12 -> 1.130994 | AM12: 11
A13: 2006 | B13: 540566 | C13: =B13/U13 -> 4.2264408 | D13: =C13/C12 -> 1.004873 | E13: 0.7 | F13: 293508.6 | G13: =SUM(H13:J13) -> 119256.3 | H13: 27354.6 | I13: 91710.1 | J13: 191.6 | K13: =SUM(L13:N13) -> 120862.9 | L13: 93706.1 | M13: 27159 | N13: -2.2 | O13: =B13-P13 -> 115174.4 | P13: 425391.6 | Q13: 100.5 | R13: =(Q13/Q12-1)*100 -> -0.98522167 | S13: 99.7 | T13: =U13-V13 -> 110466 | U13: 127901 | V13: 17435 | W13: 6664 | X13: 6389 | Y13: 275 | Z13: =AA13/AD13*100 -> 93.137255 | AA13: =AB13 -> 104.5 | AB13: 104.5 | AC13: 0.2 | AD13: =AE13 -> 112.2 | AE13: 112.2 | AF13: 0.5 | AG13: 95.5 | AH13: =(AG13/AG12-1)*100 -> 0.31512605 | AI13: 1.6648333 | AJ13: 109.78333 | AK13: 111.45 | AL13: =AJ13/AK13 -> 0.98504561 | AM13: 12
A14: 2007 | B14: 544571.1 | C14: =B14/U14 -> 4.2533651 | D14: =C14/C13 -> 1.0063705 | E14: 0.2 | F14: 294745.1 | G14: =SUM(H14:J14) -> 119838.3 | H14: 25245.5 | I14: 92758.7 | J14: 1834.1 | K14: =SUM(L14:N14) -> 120498.8 | L14: 94372.8 | M14: 26078.1 | N14: 47.9 | O14: =B14-P14 -> 118188.5 | P14: 426382.6 | Q14: 99.5 | R14: =(Q14/Q13-1)*100 -> -0.99502488 | S14: 99.3 | T14: =U14-V14 -> 110740 | U14: 128033 | V14: 17293 | W14: 6684 | X14: 6427 | Y14: 257 | Z14: =AA14/AD14*100 -> 92.908438 | AA14: =AB14 -> 103.5 | AB14: 103.5 | AC14: -0.9 | AD14: =AE14 -> 111.4 | AE14: 111.4 | AF14: -0.8 | AG14: 95.5 | AH14: =(AG14/AG13-1)*100 -> 0 | AI14: 1.88325 | AJ14: 110.04167 | AK14: 119.84167 | AL14: =AJ14/AK14 -> 0.91822544 | AM14: 13
A15: 2008 | B15: 533355.4 | C15: =B15/U15 -> 4.1641064 | D15: =C15/C14 -> 0.97901455 | E15: -3.9 | F15: 293475.4 | G15: =SUM(H15:J15) -> 118293.8 | H15: 24333 | I15: 90952.9 | J15: 3007.9 | K15: =SUM(L15:N15) -> 119792.2 | L15: 94304.4 | M15: 25450.4 | N15: 37.4 | O15: =B15-P15 -> 139816.8 | P15: 393538.6 | Q15: 98.6 | R15: =(Q15/Q14-1)*100 -> -0.90452261 | S15: 100 | T15: =U15-V15 -> 110908 | U15: 128084 | V15: 17176 | W15: 6674 | X15: 6409 | Y15: 265 | Z15: =AA15/AD15*100 -> 93.738657 | AA15: =AB15 -> 103.3 | AB15: 103.3 | AC15: -0.3 | AD15: =AE15 -> 110.2 | AE15: 110.2 | AF15: -1.2 | AG15: 96.8 | AH15: =(AG15/AG14-1)*100 -> 1.3612565 | AI15: 1.9095 | AJ15: 112.325 | AK15: 130.15 | AL15: =AJ15/AK15 -> 0.86304264 | AM15: 14
A16: 2009 | B16: 499361.7 | C16: =B16/U16 -> 3.9002882 | D16: =C16/C15 -> 0.93664471 | E16: -4.1 | F16: 283897.2 | G16: =SUM(H16:J16) -> 91724.6 | H16: 19546.4 | I16: 77307.6 | J16: -5129.4 | K16: =SUM(L16:N16) -> 121523.2 | L16: 95100.8 | M16: 26408.5 | N16: 13.9 | O16: =B16-P16 -> 118820.8 | P16: 380540.9 | Q16: 98.2 | R16: =(Q16/Q15-1)*100 -> -0.40567951 | S16: 97.6 | T16: =U16-V16 -> 111021 | U16: 128032 | V16: 17011 | W16: 6650 | X16: 6314 | Y16: 336 | Z16: =AA16/AD16*100 -> 92.803738 | AA16: =AB16 -> 99.3 | AB16: 99.3 | AC16: -3.8 | AD16: =AE16 -> 107 | AE16: 107 | AF16: -2.8 | AG16: 95.5 | AH16: =(AG16/AG15-1)*100 -> -1.3429752 | AI16: 1.7233333 | AJ16: 108.64167 | AK16: 97.108333 | AL16: =AJ16/AK16 -> 1.1187677 | AM16: 15
A17: 2010 | B17: 510139.6 | C17: =B17/U17 -> 3.9836916 | D17: =C17/C16 -> 1.0213839 | E17: 1.7 | F17: 286441 | G17: =SUM(H17:J17) -> 94525 | H17: 19290.6 | I17: 75167.1 | J17: 67.3 | K17: =SUM(L17:N17) -> 122411.9 | L17: 96685.6 | M17: 25749.1 | N17: -22.8 | O17: =B17-P17 -> 116293.3 | P17: 393846.3 | Q17: 96.3 | R17: =(Q17/Q16-1)*100 -> -1.9348269 | S17: 96.2 | T17: =U17-V17 -> 111254 | U17: 128057 | V17: 16803 | W17: 6632 | X17: 6298 | Y17: 334 | Z17: =AA17/AD17*100 -> 91.98895 | AA17: =AB17 -> 99.9 | AB17: 99.9 | AC17: 0.6 | AD17: =AE17 -> 108.6 | AE17: 108.6 | AF17: 1.5 | AG17: 94.8 | AH17: =(AG17/AG16-1)*100 -> -0.73298429 | AI17: 1.5983333 | AJ17: 110.96667 | AK17: 104.00833 | AL17: =AJ17/AK17 -> 1.0669017 | AM17: 16
A18: 2011 | B18: 501142 | C18: =B18/U18 -> 3.920256 | D18: =C18/C17 -> 0.98407616 | E18: -1 | F18: 283221.5 | G18: =SUM(H18:J18) -> 98202.3 | H18: 20710.9 | I18: 76572.7 | J18: 918.7 | K18: =SUM(L18:N18) -> 122937.1 | L18: 98602.3 | M18: 24310.9 | N18: 23.9 | O18: =B18-P18 -> 113477.5 | P18: 387664.5 | Q18: 94.8 | R18: =(Q18/Q17-1)*100 -> -1.5576324 | S18: 95.7 | T18: =U18-V18 -> 111129 | U18: 127834 | V18: 16705 | W18: 6596 | X18: 6293 | Y18: 302 | Z18: =AA18/AD18*100 -> 92.059095 | AA18: =AB18 -> 99.7 | AB18: 99.7 | AC18: -0.3 | AD18: =AE18 -> 108.3 | AE18: 108.3 | AF18: -0.3 | AG18: 94.5 | AH18: =(AG18/AG17-1)*100 -> -0.3164557 | AI18: 1.5009167 | AJ18: 114.41667 | AK18: 111.79167 | AL18: =AJ18/AK18 -> 1.0234812 | AM18: 17
A19: 2012 | B19: 505377.1 | C19: =B19/U19 -> 3.9608529 | D19: =C19/C18 -> 1.0103557 | E19: 0.1 | F19: 287611.1 | G19: =SUM(H19:J19) -> 101490.5 | H19: 20983.5 | I19: 79409.3 | J19: 1097.7 | K19: =SUM(L19:N19) -> 124495.2 | L19: 99708.4 | M19: 24742.5 | N19: 44.3 | O19: =B19-P19 -> 116089.5 | P19: 389287.6 | Q19: 94.1 | R19: =(Q19/Q18-1)*100 -> -0.73839662 | S19: 95.1 | T19: =U19-V19 -> 111046 | U19: 127593 | V19: 16547 | W19: 6565 | X19: 6280 | Y19: 285 | Z19: =AA19/AD19*100 -> 90.725436 | AA19: =AB19 -> 98.8 | AB19: 98.8 | AC19: -0.8 | AD19: =AE19 -> 108.9 | AE19: 108.9 | AF19: 0.5 | AG19: 94.5 | AH19: =(AG19/AG18-1)*100 -> 0 | AI19: 1.4075 | AJ19: 112.75 | AK19: 111.55833 | AL19: =AJ19/AK19 -> 1.010682 | AM19: 18
A20: 2013 | B20: 514553.3 | C20: =B20/U20 -> 4.0384361 | D20: =C20/C19 -> 1.0195875 | E20: 2.9 | F20: 295249.4 | G20: =SUM(H20:J20) -> 104172.8 | H20: 23039.3 | I20: 81868 | J20: -734.5 | K20: =SUM(L20:N20) -> 127397.7 | L20: 101012.3 | M20: 26404.6 | N20: -19.2 | O20: =B20-P20 -> 109296.3 | P20: 405257 | Q20: 93.9 | R20: =(Q20/Q19-1)*100 -> -0.21253985 | S20: 95 | T20: =U20-V20 -> 111024 | U20: 127414 | V20: 16390 | W20: 6593 | X20: 6326 | Y20: 265 | Z20: =AA20/AD20*100 -> 91.457753 | AA20: =AB20 -> 98.5 | AB20: 98.5 | AC20: -0.2 | AD20: =AE20 -> 107.7 | AE20: 107.7 | AF20: -1.1 | AG20: 94.9 | AH20: =(AG20/AG19-1)*100 -> 0.42328042 | AI20: 1.30375 | AJ20: 110.70833 | AK20: 127.70833 | AL20: =AJ20/AK20 -> 0.86688418 | AM20: 19
... A30: 2023 | B30: 616033 | C30: =B30/U30 -> 4.9517153 | D30: =C30/C29 -> 1.0580524 | E30: 4.7 | F30: 330179.7 | G30: =SUM(H30:J30) -> 140353.3 | H30: 26785.4 | I30: 113786.1 | J30: -218.2 | K30: =SUM(L30:N30) -> 154595.4 | L30: 123789.5 | M30: 30979.5 | N30: -173.6 | O30: =B30-P30 -> 133596.2 | P30: 482436.8 | Q30: 105.1 | R30: =(Q30/Q29-1)*100 -> 4.473161 | S30: 107.9 | T30: =U30-V30 -> 110206 | U30: 124408 | V30: 14202 | W30: 6925 | X30: 6747 | Y30: 178 | Z30: =AA30/AD30*100 -> 102.57681 | AA30: =AB30 -> 103.5 | AB30: 103.5 | AC30: 1.2 | AD30: =AE30 -> 100.9 | AE30: 100.9 | AF30: 0.1 | AG30: 105.6 | AH30: =(AG30/AG29-1)*100 -> 3.2258065 | AI30: 0.77691667 | AJ30: 110.50833 | AK30: 161.20833 | AL30: =AJ30/AK30 -> 0.68550013 | AM30: 29
A31: 2024 | B31: 634226 | C31: =B31/U31 -> 5.1211686 | D31: =C31/C30 -> 1.0342211 | E31: 3.7 | F31: 336580.9 | G31: =SUM(H31:J31) -> 144166.6 | H31: 27249 | I31: 117611.9 | J31: -694.3 | K31: =SUM(L31:N31) -> 159143 | L31: 127761 | M31: 31540.4 | N31: -158.4 | O31: =B31-P31 -> 137572.1 | P31: 496653.9 | Q31: 108.5 | R31: =(Q31/Q30-1)*100 -> 3.2350143 | S31: 110.6 | T31: =U31-V31 -> 109929 | U31: 123844 | V31: 13915 | W31: 6957 | X31: 6781 | Y31: 176 | Z31: =AA31/AD31*100 -> 106.5141 | AA31: =AA30*(1+AC31/100) -> 106.398 | AB31: 109.2 | AC31: 2.8 | AD31: =AD30*(1+AF31/100) -> 99.891 | AE31: 101.4 | AF31: -1 | AG31: 108.5 | AH31: =(AG31/AG30-1)*100 -> 2.7462121 | AI31: 0.84183333 | AJ31: 112.6 | AK31: 165.54167 | AL31: =AJ31/AK31 -> 0.68019129 | AM31: 30
A32: 2025 | B32: 663757.3 | C32: =B32/U32 -> 5.3849305 | D32: =C32/C31 -> 1.0515042 | E32: 4.2 | F32: 351588 | G32: =SUM(H32:J32) -> 151590 | H32: 27449.6 | I32: 123514.3 | J32: 626.1 | K32: =SUM(L32:N32) -> 164108.2 | L32: 131654.5 | M32: 32524 | N32: -70.3 | O32: =B32-P32 -> 151540.05 | P32: =P31*(AG32/AG31) -> 512217.25 | Q32: 112.2 | R32: =(Q32/Q31-1)*100 -> 3.4101382 | S32: 113.9 | T32: =U32-V32 -> 109629 | U32: 123262 | V32: 13633 | W32: 7004 | X32: 6828 | Y32: 176 | Z32: =AA32/AD32*100 -> 110.51108 | AA32: =AA31*(1+AC32/100) -> 108.84515 | AB32: 111.7 | AC32: 2.3 | AD32: =AD31*(1+AF32/100) -> 98.492526 | AE32: 100 | AF32: -1.4 | AG32: 111.9 | AH32: =(AG32/AG31-1)*100 -> 3.1336406 | AI32: 1.1035 | AJ32: 112.80833 | AK32: 158.425 | AL32: =AJ32/AK32 -> 0.71206144 | AM32: 31
A33: 2026 | B33: =B32*(1+E33/100) -> 686325.05 | C33: =B33/U33 -> 5.5952996 | D33: =C33/C32 -> 1.0390663 | E33: 3.4 | F33: =F32*(1+$E33/100) -> 363541.99 | G33: =G32*(1+$E33/100) -> 156744.06 | Q33: =Q32*(1+R33/100) -> 114.444 | R33: 2 | S33: =S32*(1+R33/100) -> 116.178 | T33: =U33-V33 -> 109306 | U33: 122661 | V33: 13355 | AD33: =_xlfn.FORECAST.LINEAR(AM33,AD2:AD32,AM2:AM32) -> 99.023739 | AG33: =AG32*(1+AH33/100) -> 114.0261 | AH33: 1.9 | AL33: =AL32 -> 0.71206144 | AM33: 32
A34: 2027 | B34: =B33*(1+E34/100) -> 697306.25 | C34: =B34/U34 -> 5.7135644 | D34: =C34/C33 -> 1.0211364 | E34: 1.6 | F34: =F33*(1+$E34/100) -> 369358.66 | G34: =G33*(1+$E34/100) -> 159251.96 | Q34: =Q33*(1+R34/100) -> 115.70288 | R34: 1.1 | S34: =S33*(1+R34/100) -> 117.45596 | T34: =U34-V34 -> 108944 | U34: 122044 | V34: 13100 | AD34: =_xlfn.FORECAST.LINEAR(AM34,AD3:AD33,AM3:AM33) -> 98.439811 | AG34: =AG33*(1+AH34/100) -> 115.62247 | AH34: 1.4 | AL34: =AL33 -> 0.71206144 | AM34: 33
A35: 2028 | B35: =B34*(1+E35/100) -> 705673.92 | C35: =B35/U35 -> 5.8121298 | D35: =C35/C34 -> 1.0172511 | E35: 1.2 | F35: =F34*(1+$E35/100) -> 373790.97 | G35: =G34*(1+$E35/100) -> 161162.99 | Q35: =Q34*(1+R35/100) -> 116.5128 | R35: 0.7 | S35: =S34*(1+R35/100) -> 118.27815 | T35: =U35-V35 -> 108564 | U35: 121414 | V35: 12850 | AD35: =_xlfn.FORECAST.LINEAR(AM35,AD4:AD34,AM4:AM34) -> 97.908772 | AG35: =AG34*(1+AH35/100) -> 116.89431 | AH35: 1.1 | AL35: =AL34 -> 0.71206144 | AM35: 34
A36: 2029 | B36: =B35*(1+E36/100) -> 714142.01 | C36: =B36/U36 -> 5.9131912 | D36: =C36/C35 -> 1.017388 | E36: 1.2 | F36: =F35*(1+$E36/100) -> 378276.46 | G36: =G35*(1+$E36/100) -> 163096.94 | Q36: =Q35*(1+R36/100) -> 117.32839 | R36: 0.7 | S36: =S35*(1+R36/100) -> 119.1061 | T36: =U36-V36 -> 108146 | U36: 120771 | V36: 12625 | AD36: =_xlfn.FORECAST.LINEAR(AM36,AD5:AD35,AM5:AM35) -> 97.321214 | AG36: =AG35*(1+AH36/100) -> 118.18015 | AH36: 1.1 | AL36: =AL35 -> 0.71206144 | AM36: 35
A37: 2030 | B37: =B36*(1+E37/100) -> 722711.72 | C37: =B37/U37 -> 6.0167814 | D37: =C37/C36 -> 1.0175185 | E37: 1.2 | F37: =F36*(1+$E37/100) -> 382815.78 | G37: =G36*(1+$E37/100) -> 165054.11 | Q37: =Q36*(1+R37/100) -> 118.14969 | R37: 0.7 | S37: =S36*(1+R37/100) -> 119.93984 | T37: =U37-V37 -> 107719 | U37: 120116 | V37: 12397 | AD37: =_xlfn.FORECAST.LINEAR(AM37,AD6:AD36,AM6:AM36) -> 96.684236 | AG37: =AG36*(1+AH37/100) -> 119.48013 | AH37: 1.1 | AL37: =AL36 -> 0.71206144 | AM37: 36
A38: 2031 | B38: =B37*(1+E38/100) -> 731384.26 | C38: =B38/U38 -> 6.1230348 | D38: =C38/C37 -> 1.0176595 | E38: 1.2 | F38: =F37*(1+$E38/100) -> 387409.57 | G38: =G37*(1+$E38/100) -> 167034.76 | Q38: =Q37*(1+R38/100) -> 118.97674 | R38: 0.7 | S38: =S37*(1+R38/100) -> 120.77942 | T38: =U38-V38 -> 107255 | U38: 119448 | V38: 12193 | AD38: =_xlfn.FORECAST.LINEAR(AM38,AD7:AD37,AM7:AM37) -> 95.986866 | AG38: =AG37*(1+AH38/100) -> 120.79441 | AH38: 1.1 | AL38: =AL37 -> 0.71206144 | AM38: 37
A39: 2032 | B39: =B38*(1+E39/100) -> 740160.87 | C39: =B39/U39 -> 6.2320939 | D39: =C39/C38 -> 1.0178113 | E39: 1.2 | F39: =F38*(1+$E39/100) -> 392058.48 | G39: =G38*(1+$E39/100) -> 169039.17 | Q39: =Q38*(1+R39/100) -> 119.80958 | R39: 0.7 | S39: =S38*(1+R39/100) -> 121.62487 | T39: =U39-V39 -> 106740 | U39: 118766 | V39: 12026 | AD39: =_xlfn.FORECAST.LINEAR(AM39,AD8:AD38,AM8:AM38) -> 95.366066 | AG39: =AG38*(1+AH39/100) -> 122.12315 | AH39: 1.1 | AL39: =AL38 -> 0.71206144 | AM39: 38
A40: 2033 | B40: =B39*(1+E40/100) -> 749042.8 | C40: =B40/U40 -> 6.3440032 | D40: =C40/C39 -> 1.0179569 | E40: 1.2 | F40: =F39*(1+$E40/100) -> 396763.18 | G40: =G39*(1+$E40/100) -> 171067.64 | Q40: =Q39*(1+R40/100) -> 120.64824 | R40: 0.7 | S40: =S39*(1+R40/100) -> 122.47625 | T40: =U40-V40 -> 106192 | U40: 118071 | V40: 11879 | AD40: =_xlfn.FORECAST.LINEAR(AM40,AD9:AD39,AM9:AM39) -> 94.699441 | AG40: =AG39*(1+AH40/100) -> 123.46651 | AH40: 1.1 | AL40: =AL39 -> 0.71206144 | AM40: 39
A41: 2034 | B41: =B40*(1+E41/100) -> 757282.27 | C41: =B41/U41 -> 6.4525338 | D41: =C41/C40 -> 1.0171076 | E41: 1.1 | F41: =F40*(1+$E41/100) -> 401127.58 | G41: =G40*(1+$E41/100) -> 172949.39 | Q41: =Q40*(1+R41/100) -> 121.49278 | R41: 0.7 | S41: =S40*(1+R41/100) -> 123.33358 | T41: =U41-V41 -> 105591 | U41: 117362 | V41: 11771 | AD41: =_xlfn.FORECAST.LINEAR(AM41,AD10:AD40,AM10:AM40) -> 93.984438 | AG41: =AG40*(1+AH41/100) -> 124.82464 | AH41: 1.1 | AL41: =AL40 -> 0.71206144 | AM41: 40
A42: 2035 | B42: =B41*(1+E42/100) -> 765612.37 | C42: =B42/U42 -> 6.5639484 | D42: =C42/C41 -> 1.0172668 | E42: 1.1 | F42: =F41*(1+$E42/100) -> 405539.98 | G42: =G41*(1+$E42/100) -> 174851.83 | Q42: =Q41*(1+R42/100) -> 122.34323 | R42: 0.7 | S42: =S41*(1+R42/100) -> 124.19692 | T42: =U42-V42 -> 104948 | U42: 116639 | V42: 11691 | AD42: =_xlfn.FORECAST.LINEAR(AM42,AD11:AD41,AM11:AM41) -> 93.290084 | AG42: =AG41*(1+AH42/100) -> 126.19771 | AH42: 1.1 | AL42: =AL41 -> 0.71206144 | AM42: 41
A43: 2036 | B43: =B42*D43*(U43/U42) -> 773910.89 | D43: =D42 -> 1.0172668 | E43: =B43/B42*100-100 -> 1.0839054 | F43: =F42*(1+$E43/100) -> 409935.65 | G43: =G42*(1+$E43/100) -> 176747.06 | Q43: =Q42*(1+R43/100) -> 123.19963 | R43: =R42 -> 0.7 | S43: =S42*(1+R43/100) -> 125.0663 | T43: =U43-V43 -> 104297 | U43: 115902 | V43: 11605 | AD43: =_xlfn.FORECAST.LINEAR(AM43,AD12:AD42,AM12:AM42) -> 92.637849 | AG43: =AG42*(1+AH43/100) -> 127.58588 | AH43: =AH42 -> 1.1 | AL43: =AL42 -> 0.71206144 | AM43: 42
A44: 2037 | B44: =B43*D44*(U44/U43) -> 782179.41 | D44: =D43 -> 1.0172668 | E44: =B44/B43*100-100 -> 1.068408 | F44: =F43*(1+$E44/100) -> 414315.44 | G44: =G43*(1+$E44/100) -> 178635.44 | Q44: =Q43*(1+R44/100) -> 124.06203 | R44: =R43 -> 0.7 | S44: =S43*(1+R44/100) -> 125.94176 | T44: =U44-V44 -> 103601 | U44: 115152 | V44: 11551 | AD44: =_xlfn.FORECAST.LINEAR(AM44,AD13:AD43,AM13:AM43) -> 91.975067 | AG44: =AG43*(1+AH44/100) -> 128.98933 | AH44: =AH43 -> 1.1 | AL44: =AL43 -> 0.71206144 | AM44: 43
A45: 2038 | B45: =B44*D45*(U45/U44) -> 790426.74 | D45: =D44 -> 1.0172668 | E45: =B45/B44*100-100 -> 1.0544031 | F45: =F44*(1+$E45/100) -> 418683.99 | G45: =G44*(1+$E45/100) -> 180518.98 | Q45: =Q44*(1+R45/100) -> 124.93047 | R45: =R44 -> 0.7 | S45: =S44*(1+R45/100) -> 126.82335 | T45: =U45-V45 -> 102871 | U45: 114391 | V45: 11520 | AD45: =_xlfn.FORECAST.LINEAR(AM45,AD14:AD44,AM14:AM44) -> 91.38523 | AG45: =AG44*(1+AH45/100) -> 130.40821 | AH45: =AH44 -> 1.1 | AL45: =AL44 -> 0.71206144 | AM45: 44
A46: 2039 | B46: =B45*D46*(U46/U45) -> 798648.35 | D46: =D45 -> 1.0172668 | E46: =B46/B45*100-100 -> 1.0401485 | F46: =F45*(1+$E46/100) -> 423038.93 | G46: =G45*(1+$E46/100) -> 182396.64 | Q46: =Q45*(1+R46/100) -> 125.80498 | R46: =R45 -> 0.7 | S46: =S45*(1+R46/100) -> 127.71112 | T46: =U46-V46 -> 102145 | U46: 113619 | V46: 11474 | AD46: =_xlfn.FORECAST.LINEAR(AM46,AD15:AD45,AM15:AM45) -> 90.792995 | AG46: =AG45*(1+AH46/100) -> 131.8427 | AH46: =AH45 -> 1.1 | AL46: =AL45 -> 0.71206144 | AM46: 45
A47: 2040 | B47: =B46*D47*(U47/U46) -> 806846.72 | D47: =D46 -> 1.0172668 | E47: =B47/B46*100-100 -> 1.0265305 | F47: =F46*(1+$E47/100) -> 427381.55 | G47: =G46*(1+$E47/100) -> 184269 | Q47: =Q46*(1+R47/100) -> 126.68561 | R47: =R46 -> 0.7 | S47: =S46*(1+R47/100) -> 128.60509 | T47: =U47-V47 -> 101418 | U47: 112837 | V47: 11419 | AD47: =_xlfn.FORECAST.LINEAR(AM47,AD16:AD46,AM16:AM46) -> 90.168308 | AG47: =AG46*(1+AH47/100) -> 133.29297 | AH47: =AH46 -> 1.1 | AL47: =AL46 -> 0.71206144 | AM47: 46
A48: 2041 | T48: =U48-V48 -> 100685 | U48: 112045 | V48: 11360
A49: 2042 | T49: =U49-V49 -> 99951 | U49: 111243 | V49: 11292
...

Sheet Sheet3
A1: 1.9 | B1: 1.4 | C1: 1.1 | D1: 1.1 | E1: 1.1 | F1: 1.1 | G1: 1.1 | H1: 1.1 | I1: 1.1 | J1: 1.1 | K1: -0.3 | L1: 0.9 | M1: 2.9 | N1: 0.2 | O1: -0.1 | P1: 0.7 | Q1: 0.7 | R1: 0.5 | S1: -0.2 | T1: 0.1 | U1: 3.2 | V1: 3 | W1: 3 | X1: 2.6 | Y1: 1.9 | Z1: 1.4 | AA1: 1.1 | AB1: 1.1 | AC1: 1.1 | AD1: 1.1 | AE1: 1.1 | AF1: 1.1 | AG1: 1.1 | AH1: 1.1
