Workbook

Sheet List of contents
A1: JIP2023資本データ
A3: 1) 部門別・資産別投資及び資本ストック | B3: 単位 | C3: 推計対象期間
A4: i) 部門別名目投資フロー | B4: 100万円 | C4: 1995年～2020年
A5: ii) 部門別実質投資フロー | B5: 100万円、2015年価格 | C5: 1995年～2020年
A6: iii) 部門別資本投入指数 | B6: 2015年=1.000 | C6: 1994年～2020年
A7: iv) 部門別資本の質指数 | B7: 2015年=1.000 | C7: 1994年～2020年
A8: v) 部門別名目純資本ストック | B8: 100万円 | C8: 1994年～2020年
A9: vi) 部門別実質純資本ストック | B9: 100万円、2015年価格 | C9: 1994年～2020年
A10: vii) 部門別名目資本コスト (名目資本サービス価格*実質資本ストック) | B10: 100万円 | C10: 1994年～2020年
A11: viii) 資産別名目投資フロー | B11: 100万円 | C11: 1995年～2020年
A12: ix) 資産別実質投資フロー | B12: 100万円、2015年価格 | C12: 1995年～2020年
A13: x) 資産別名目純資本ストック | B13: 100万円 | C13: 1994年～2020年
A14: xi) 資産別実質純資本ストック | B14: 100万円、2015年価格 | C14: 1994年～2020年
... A22: v) 名目資本コスト・マトリックス | B22: 100万円 | C22: 1994年～2020年

Sheet 部門別名目投資フロー
A1: 部門別名目投資フロー (100万円)
A2: JIP部門分類 | C2: 1994 | D2: 1995 | E2: 1996 | F2: 1997 | G2: 1998 | H2: 1999 | I2: 2000 | J2: 2001 | K2: 2002 | L2: 2003 | M2: 2004 | N2: 2005 | O2: 2006 | P2: 2007 | Q2: 2008 | R2: 2009 | S2: 2010 | T2: 2011 | U2: 2012 | V2: 2013 | W2: 2014 | X2: 2015 | Y2: 2016 | Z2: 2017 | AA2: 2018 | AB2: 2019 | AC2: 2020
A3: 1 | B3: 農業 | D3: 2947241.9 | E3: 2755370.9 | F3: 2755364.2 | G3: 2975821.1 | H3: 2764025.1 | I3: 2154572.3 | J3: 1945035.4 | K3: 1795856.7 | L3: 1865867.6 | M3: 1743762.9 | N3: 1733441.5 | O3: 1400356 | P3: 1337695 | Q3: 1317436.4 | R3: 1196211.7 | S3: 1201716 | T3: 1096173.5 | U3: 1223425.1 | V3: 1394861.1 | W3: 1328826.9 | X3: 1427312.5 | Y3: 1275649.1 | Z3: 1796904.3 | AA3: 1279521.9 | AB3: 1260263.1 | AC3: 1287239.4
A4: 2 | B4: 農業サービス | D4: 287595.36 | E4: 248235.84 | F4: 238180.42 | G4: 249636.59 | H4: 222526.54 | I4: 173129.65 | J4: 149610.47 | K4: 130589.79 | L4: 126672.73 | M4: 103102.98 | N4: 98088.028 | O4: 82893.475 | P4: 80869.603 | Q4: 75167.801 | R4: 69646.384 | S4: 60214.38 | T4: 69878.141 | U4: 79852.276 | V4: 84241.844 | W4: 63152.126 | X4: 81630.855 | Y4: 56126.011 | Z4: 55968.293 | AA4: 74119.66 | AB4: 48780.634 | AC4: 45713.399
A5: 3 | B5: 林業 | D5: 60440.646 | E5: 46688.572 | F5: 67224.981 | G5: 34035.947 | H5: 55846.205 | I5: 30754.01 | J5: 75183.46 | K5: 73264.87 | L5: 52510.858 | M5: 69871.856 | N5: 53051.578 | O5: 35360.734 | P5: 43831.912 | Q5: 35960.36 | R5: 33751.603 | S5: 32775.277 | T5: 26818.577 | U5: 33742.584 | V5: 36728.281 | W5: 24822.461 | X5: 38353.636 | Y5: 32828.831 | Z5: 44036.095 | AA5: 58849.947 | AB5: 34004.95 | AC5: 27268.754
A6: 4 | B6: 漁業 | D6: 607272.51 | E6: 480604.09 | F6: 465357.29 | G6: 287739.92 | H6: 146093.92 | I6: 327450.96 | J6: 356853.43 | K6: 236657.18 | L6: 132538.23 | M6: 241845.09 | N6: 216064.4 | O6: 171329.42 | P6: 127783.21 | Q6: 145782.5 | R6: 143723.89 | S6: 153954.03 | T6: 145450.11 | U6: 175171.25 | V6: 184885.54 | W6: 122708.01 | X6: 184889.8 | Y6: 158202.71 | Z6: 211903.26 | AA6: 282665.2 | AB6: 163703.63 | AC6: 131183.89
A7: 5 | B7: 鉱業 | D7: 239200 | E7: 169500 | F7: 168700 | G7: 170600 | H7: 131200 | I7: 164900 | J7: 140000 | K7: 172800 | L7: 112300 | M7: 106100 | N7: 110000 | O7: 124400 | P7: 148100 | Q7: 165300 | R7: 136500 | S7: 113000 | T7: 121600 | U7: 116800 | V7: 190400 | W7: 211500 | X7: 210500 | Y7: 187200 | Z7: 250700 | AA7: 140900 | AB7: 115500 | AC7: 89900
A8: 6 | B8: 畜産食料品 | D8: 305848.57 | E8: 282359.16 | F8: 273370.17 | G8: 304459.53 | H8: 322928.5 | I8: 334446.4 | J8: 361999.09 | K8: 337690.04 | L8: 297250.74 | M8: 304051.78 | N8: 306718.84 | O8: 390938.32 | P8: 367304.79 | Q8: 289942.37 | R8: 270315.13 | S8: 269323.28 | T8: 309286.35 | U8: 300941.08 | V8: 317723.18 | W8: 314198.71 | X8: 368999.89 | Y8: 390913.92 | Z8: 419807.71 | AA8: 434967.22 | AB8: 447187.28 | AC8: 388058.63
A9: 7 | B9: 水産食料品 | D9: 148714.86 | E9: 128698.83 | F9: 137202.98 | G9: 108180.4 | H9: 98850.939 | I9: 95307.374 | J9: 86910.731 | K9: 77578.879 | L9: 75068.181 | M9: 92965.171 | N9: 119110.42 | O9: 104500.19 | P9: 119165.75 | Q9: 96653.18 | R9: 85384.836 | S9: 86222.295 | T9: 102604.65 | U9: 111942.91 | V9: 112751.07 | W9: 109629.86 | X9: 106733.02 | Y9: 140759.47 | Z9: 138834.04 | AA9: 132253.89 | AB9: 104994.96 | AC9: 115987.04
A10: 8 | B10: 精穀・製粉 | D10: 46296.451 | E10: 56175.645 | F10: 46695.354 | G10: 44035.39 | H10: 41336.687 | I10: 50960.116 | J10: 41977.118 | K10: 59295.016 | L10: 47664.96 | M10: 42039.261 | N10: 49388.077 | O10: 60544.753 | P10: 42641.108 | Q10: 43784.8 | R10: 30157.941 | S10: 33423.182 | T10: 42814.256 | U10: 39719.08 | V10: 29901.719 | W10: 28046.239 | X10: 28611.126 | Y10: 35137.464 | Z10: 32780.139 | AA10: 36189.494 | AB10: 30073.997 | AC10: 44392.158
A11: 9 | B11: その他の食料品 | D11: 803954.98 | E11: 819363.76 | F11: 811983.72 | G11: 817241.98 | H11: 762870.67 | I11: 811328.48 | J11: 837641.91 | K11: 864523.9 | L11: 828624.93 | M11: 904518.09 | N11: 952955.45 | O11: 1084941.6 | P11: 1045679.3 | Q11: 877899.64 | R11: 857093.53 | S11: 832330.5 | T11: 995714.31 | U11: 934133.44 | V11: 866832.3 | W11: 919778.03 | X11: 886424.67 | Y11: 1121358.9 | Z11: 1218563.3 | AA11: 1254431.3 | AB11: 1120860.5 | AC11: 1026689.7
A12: 10 | B12: 飲料 | D12: 743840.18 | E12: 698457.8 | F12: 951648.47 | G12: 993501.56 | H12: 806916.24 | I12: 781221.66 | J12: 670019.01 | K12: 675026.25 | L12: 578393.2 | M12: 495663.59 | N12: 658531.34 | O12: 577741.21 | P12: 637220.66 | Q12: 550053.64 | R12: 470034.53 | S12: 452264.35 | T12: 581819.34 | U12: 546503.81 | V12: 415104.35 | W12: 466020.24 | X12: 439800.02 | Y12: 425465.39 | Z12: 503404.13 | AA12: 446975.97 | AB12: 525797.62 | AC12: 326360.41
A13: 11 | B13: 飼料・有機質肥料 | D13: 84386.393 | E13: 100491.73 | F13: 87981.631 | G13: 109243.74 | H13: 99707.193 | I13: 96383.537 | J13: 65234.059 | K13: 56879.136 | L13: 57020.591 | M13: 46758.628 | N13: 45711.198 | O13: 30866.904 | P13: 35865.611 | Q13: 42545.39 | R13: 58448.01 | S13: 43160.779 | T13: 57125.329 | U13: 66527.992 | V13: 41611.481 | W13: 48268.645 | X13: 52699.629 | Y13: 51186.208 | Z13: 70761.624 | AA13: 70284.557 | AB13: 68737.504 | AC13: 84781.261
A14: 12 | B14: たばこ | D14: 146858.57 | E14: 257553.07 | F14: 125117.68 | G14: 134137.41 | H14: 153789.77 | I14: 187052.42 | J14: 289718.08 | K14: 188706.77 | L14: 143477.4 | M14: 166503.49 | N14: 217384.68 | O14: 82767.029 | P14: 148422.74 | Q14: 177220.97 | R14: 143066.02 | S14: 162475.62 | T14: 140935.77 | U14: 100331.69 | V14: 126575.9 | W14: 156058.29 | X14: 140431.65 | Y14: 78578.674 | Z14: 89249.012 | AA14: 122597.59 | AB14: 80948.142 | AC14: 80430.829
... A101: 99 | B101: 会員制団体 | D101: 543735.95 | E101: 757467.08 | F101: 677671.05 | G101: 677103.31 | H101: 808075.29 | I101: 666445.52 | J101: 566488.42 | K101: 378994.41 | L101: 621001.14 | M101: 788241.24 | N101: 752860.97 | O101: 577012.96 | P101: 535741.95 | Q101: 811888.84 | R101: 614121.72 | S101: 501615.31 | T101: 467775.39 | U101: 408382.69 | V101: 480731.24 | W101: 555198.39 | X101: 490019.25 | Y101: 467456.63 | Z101: 521266.62 | AA101: 523937.87 | AB101: 449572.71 | AC101: 410292.25

Sheet 部門別実質投資フロー
A1: 部門別実質投資フロー (100万円、2015年価格)
A2: JIP部門分類 | C2: 1994 | D2: 1995 | E2: 1996 | F2: 1997 | G2: 1998 | H2: 1999 | I2: 2000 | J2: 2001 | K2: 2002 | L2: 2003 | M2: 2004 | N2: 2005 | O2: 2006 | P2: 2007 | Q2: 2008 | R2: 2009 | S2: 2010 | T2: 2011 | U2: 2012 | V2: 2013 | W2: 2014 | X2: 2015 | Y2: 2016 | Z2: 2017 | AA2: 2018 | AB2: 2019 | AC2: 2020
A3: 1 | B3: 農業 | D3: 2913833 | E3: 2684992.4 | F3: 2682072 | G3: 2973595.4 | H3: 2774598.6 | I3: 2173281.4 | J3: 1988760.3 | K3: 1902245.8 | L3: 1981991.7 | M3: 1856308.4 | N3: 1834031.5 | O3: 1469879.7 | P3: 1408629.4 | Q3: 1398208.4 | R3: 1281362.1 | S3: 1277565.1 | T3: 1171105.9 | U3: 1305620.4 | V3: 1450917.5 | W3: 1355089.3 | X3: 1427312.5 | Y3: 1257254 | Z3: 1764036.9 | AA3: 1234908.1 | AB3: 1214823 | AC3: 1262119.1
A4: 2 | B4: 農業サービス | D4: 217527.02 | E4: 185458.9 | F4: 177179.21 | G4: 188638.01 | H4: 173336.62 | I4: 142179.4 | J4: 126352.55 | K4: 115453.28 | L4: 119237.79 | M4: 100238.82 | N4: 98249.795 | O4: 82083.263 | P4: 79619.437 | Q4: 73750.206 | R4: 69577.097 | S4: 60768.506 | T4: 71320.87 | U4: 81975.502 | V4: 86005.848 | W4: 63641.278 | X4: 81630.855 | Y4: 56775.236 | Z4: 56531.289 | AA4: 74562.77 | AB4: 49052.345 | AC4: 46181.484
A5: 3 | B5: 林業 | D5: 58428.417 | E5: 44150.395 | F5: 62779.051 | G5: 32427.763 | H5: 53309.049 | I5: 29465.109 | J5: 76182.265 | K5: 76396.959 | L5: 55855.526 | M5: 74886.592 | N5: 56522.297 | O5: 37129.41 | P5: 45631.708 | Q5: 36822.336 | R5: 34902.729 | S5: 34024.445 | T5: 27849.084 | U5: 34996.858 | V5: 37674.473 | W5: 25038.099 | X5: 38353.636 | Y5: 33100.132 | Z5: 44065.222 | AA5: 58470.246 | AB5: 33627.858 | AC5: 26989.788
A6: 4 | B6: 漁業 | D6: 589886.35 | E6: 459262 | F6: 441654.95 | G6: 277043.05 | H6: 141105.85 | I6: 315960.04 | J6: 349498.45 | K6: 236102.73 | L6: 134747.01 | M6: 248579.2 | N6: 221756.72 | O6: 174313.89 | P6: 129724.28 | Q6: 146915.17 | R6: 146068.83 | S6: 157744.02 | T6: 150319.64 | U6: 180665.96 | V6: 188959.5 | W6: 123701.91 | X6: 184889.8 | Y6: 159870.6 | Z6: 213311.36 | AA6: 283567.87 | AB6: 163688.5 | AC6: 131358.71
A7: 5 | B7: 鉱業 | D7: 222340.71 | E7: 156577.08 | F7: 156019.29 | G7: 160315.39 | H7: 124421.74 | I7: 157234 | J7: 136664.93 | K7: 173275.68 | L7: 114820.65 | M7: 110839.09 | N7: 115347.44 | O7: 129249.97 | P7: 151152.87 | Q7: 166015.13 | R7: 139589.75 | S7: 116584.57 | T7: 126099.96 | U7: 120555.96 | V7: 195434.19 | W7: 213227.89 | X7: 210500 | Y7: 188746.81 | Z7: 250698.04 | AA7: 139501.66 | AB7: 113271.03 | AC7: 88022.776
A8: 6 | B8: 畜産食料品 | D8: 282342.38 | E8: 261433.86 | F8: 252340.42 | G8: 286224.64 | H8: 304896.51 | I8: 321230.31 | J8: 350472.15 | K8: 331066.87 | L8: 295778 | M8: 303865.94 | N8: 304761.3 | O8: 391277.37 | P8: 364740.47 | Q8: 285190.43 | R8: 274104.28 | S8: 275338.37 | T8: 318110.11 | U8: 310116.93 | V8: 325140.56 | W8: 316347.23 | X8: 368999.89 | Y8: 394722.29 | Z8: 421656.24 | AA8: 433800.61 | AB8: 443604.75 | AC8: 385229.94
A9: 7 | B9: 水産食料品 | D9: 136402.59 | E9: 118239.58 | F9: 125618.12 | G9: 101379.79 | H9: 93170.79 | I9: 91639.437 | J9: 84238.745 | K9: 76197.223 | L9: 74803.133 | M9: 93128.258 | N9: 118472.59 | O9: 104967.32 | P9: 118739.3 | Q9: 95332.402 | R9: 86532.245 | S9: 88335.589 | T9: 105822.49 | U9: 115661.65 | V9: 115573.91 | W9: 110506.15 | X9: 106733.02 | Y9: 142156.52 | Z9: 139506.58 | AA9: 132026.57 | AB9: 104137.89 | AC9: 115110.48
A10: 8 | B10: 精穀・製粉 | D10: 43076.74 | E10: 51978.769 | F10: 43195.176 | G10: 41567.18 | H10: 39246.839 | I10: 48836.138 | J10: 40704.375 | K10: 57902.8 | L10: 47370.615 | M10: 42004.193 | N10: 49051.778 | O10: 60449.22 | P10: 42285.298 | Q10: 42974.615 | R10: 30625.106 | S10: 34098.314 | T10: 43965.489 | U10: 40871.456 | V10: 30567.219 | W10: 28203.267 | X10: 28611.126 | Y10: 35424.159 | Z10: 32822.023 | AA10: 35920.86 | AB10: 29637.725 | AC10: 43931.11
A11: 9 | B11: その他の食料品 | D11: 741011.77 | E11: 755307.81 | F11: 745288.5 | G11: 766271.8 | H11: 719473.78 | I11: 778141.9 | J11: 811188.07 | K11: 847169.63 | L11: 824262.67 | M11: 904505.49 | N11: 947407.17 | O11: 1087689.3 | P11: 1039917.4 | Q11: 864154.93 | R11: 868958.16 | S11: 851392.82 | T11: 1024899.6 | U11: 963319.53 | V11: 887707.66 | W11: 926485.99 | X11: 886424.67 | Y11: 1131634.6 | Z11: 1223226.4 | AA11: 1250210.4 | AB11: 1110062.7 | AC11: 1017166.2
A12: 10 | B12: 飲料 | D12: 691691.37 | E12: 650197.62 | F12: 882824.66 | G12: 938885.85 | H12: 769397.98 | I12: 758801.64 | J12: 654096.6 | K12: 667982.56 | L12: 579467.73 | M12: 498595.62 | N12: 657679.31 | O12: 580485.63 | P12: 635818.56 | Q12: 543025.49 | R12: 475724.92 | S12: 462038.71 | T12: 598576.63 | U12: 562524.07 | V12: 424681.54 | W12: 469451.03 | X12: 439800.02 | Y12: 429100.33 | Z12: 505345.32 | AA12: 445436.07 | AB12: 521061.31 | AC12: 323012.69
A13: 11 | B13: 飼料・有機質肥料 | D13: 77583.052 | E13: 92753.79 | F13: 81373.744 | G13: 102062.64 | H13: 94200.535 | I13: 92427.963 | J13: 63000.585 | K13: 55682.997 | L13: 56735.786 | M13: 46749.596 | N13: 45695.93 | O13: 30809.424 | P13: 35565.213 | Q13: 41725.014 | R13: 59054.742 | S13: 43897.55 | T13: 58543.993 | U13: 68427.376 | V13: 42531.01 | W13: 48575.26 | X13: 52699.629 | Y13: 51565.842 | Z13: 70984.054 | AA13: 69970.906 | AB13: 68022.269 | AC13: 83981.06
A14: 12 | B14: たばこ | D14: 130257.67 | E14: 229239.6 | F14: 115793.29 | G14: 129272.84 | H14: 150896.88 | I14: 188937.61 | J14: 294815.68 | K14: 194491.53 | L14: 148756.58 | M14: 173932.86 | N14: 226757.41 | O14: 84848.071 | P14: 149479.02 | Q14: 173885.75 | R14: 144862.52 | S14: 164465.87 | T14: 143024.81 | U14: 102403.67 | V14: 128962.48 | W14: 156944.47 | X14: 140431.65 | Y14: 79314.608 | Z14: 89368.92 | AA14: 121765.42 | AB14: 79756.751 | AC14: 79674.029
... A101: 99 | B101: 会員制団体 | D101: 558867.56 | E101: 770524.62 | F101: 688749.9 | G101: 702733.54 | H101: 854016.58 | I101: 709012.29 | J101: 610216.18 | K101: 413693.76 | L101: 680127.64 | M101: 861789.31 | N101: 813068.17 | O101: 618695.23 | P101: 565846.51 | Q101: 836901.04 | R101: 647431.7 | S101: 531087.72 | T101: 485377.8 | U101: 424519.27 | V101: 495343.4 | W101: 559506.55 | X101: 490019.25 | Y101: 469069.19 | Z101: 516578.26 | AA101: 511374.04 | AB101: 431799.97 | AC101: 391892.9

Sheet 部門別資本投入指数
A1: 部門別資本投入指数 (2015年=1.000)
A2: JIP部門分類 | C2: 1994 | D2: 1995 | E2: 1996 | F2: 1997 | G2: 1998 | H2: 1999 | I2: 2000 | J2: 2001 | K2: 2002 | L2: 2003 | M2: 2004 | N2: 2005 | O2: 2006 | P2: 2007 | Q2: 2008 | R2: 2009 | S2: 2010 | T2: 2011 | U2: 2012 | V2: 2013 | W2: 2014 | X2: 2015 | Y2: 2016 | Z2: 2017 | AA2: 2018 | AB2: 2019 | AC2: 2020
A3: 1 | B3: 農業 | C3: 1.9495354 | D3: 1.8883464 | E3: 1.8288485 | F3: 1.7755508 | G3: 1.7440266 | H3: 1.7154102 | I3: 1.6495042 | J3: 1.5759956 | K3: 1.5052941 | L3: 1.4488361 | M3: 1.3893916 | N3: 1.3386405 | O3: 1.2684162 | P3: 1.2050536 | Q3: 1.1505514 | R3: 1.0946859 | S3: 1.048422 | T3: 1 | U3: 0.96669487 | V3: 0.9483403 | W3: 0.92637428 | X3: 0.90907481 | Y3: 0.88285336 | Z3: 0.89529468 | AA3: 0.86827976 | AB3: 0.84749963 | AC3: 0.83441424
A4: 2 | B4: 農業サービス | C4: 2.6637606 | D4: 2.6426393 | E4: 2.5708641 | F4: 2.4912892 | G4: 2.4395909 | H4: 2.3449925 | I4: 2.1845119 | J4: 2.0298545 | K4: 1.8789482 | L4: 1.746956 | M4: 1.6071667 | N4: 1.4788523 | O4: 1.3608661 | P4: 1.2666359 | Q4: 1.181935 | R4: 1.1084808 | S4: 1.0402103 | T4: 1 | U4: 0.97342526 | V4: 0.95519041 | W4: 0.90767446 | X4: 0.88944756 | Y4: 0.83745402 | Z4: 0.79363215 | AA4: 0.78098513 | AB4: 0.73698562 | AC4: 0.69702442
A5: 3 | B5: 林業 | C5: 1.5782124 | D5: 1.5357455 | E5: 1.4493471 | F5: 1.4343472 | G5: 1.3205172 | H5: 1.308955 | I5: 1.2190912 | J5: 1.2672919 | K5: 1.2990597 | L5: 1.2652945 | M5: 1.2862853 | N5: 1.261295 | O5: 1.1970354 | P5: 1.1686195 | Q5: 1.1225558 | R5: 1.0796366 | S5: 1.0457788 | T5: 1 | U5: 0.97493415 | V5: 0.95612291 | W5: 0.90610889 | X5: 0.89467797 | Y5: 0.87290304 | Z5: 0.87623721 | AA5: 0.92218263 | AB5: 0.89983124 | AC5: 0.8609609
A6: 4 | B6: 漁業 | C6: 1.9109521 | D6: 1.9677863 | E6: 1.9613544 | F6: 1.9526447 | G6: 1.8418686 | H6: 1.6694443 | I6: 1.6550207 | J6: 1.6638605 | K6: 1.5905036 | L6: 1.4563067 | M6: 1.4183439 | N6: 1.3676314 | O6: 1.2939767 | P6: 1.2018017 | Q6: 1.135196 | R6: 1.0775175 | S6: 1.0383554 | T6: 1 | U6: 0.98329139 | V6: 0.97115139 | W6: 0.91683181 | X6: 0.90921353 | Y6: 0.88668823 | Z6: 0.89831884 | AA6: 0.95578102 | AB6: 0.92796747 | AC6: 0.8819826
A7: 5 | B7: 鉱業 | C7: 1.6784442 | D7: 1.6687291 | E7: 1.6084084 | F7: 1.5520358 | G7: 1.5017111 | H7: 1.4302137 | I7: 1.4041723 | J7: 1.3560777 | K7: 1.3401825 | L7: 1.2681782 | M7: 1.1930713 | N7: 1.1282843 | O7: 1.087535 | P7: 1.0848853 | Q7: 1.0952186 | R7: 1.073648 | S7: 1.0346031 | T7: 1 | U7: 0.98428302 | V7: 1.0150731 | W7: 1.0587893 | X7: 1.0745919 | Y7: 1.067745 | Z7: 1.1121427 | AA7: 1.0773637 | AB7: 1.0325486 | AC7: 0.97645933
A8: 6 | B8: 畜産食料品 | C8: 0.61567622 | D8: 0.65720759 | E8: 0.68433713 | F8: 0.70229293 | G8: 0.72846799 | H8: 0.76491705 | I8: 0.79561533 | J8: 0.84465026 | K8: 0.88126901 | L8: 0.89726933 | M8: 0.91950376 | N8: 0.94494149 | O8: 0.99459602 | P8: 1.0314093 | Q8: 1.0248436 | R8: 1.0075564 | S8: 0.99553379 | T8: 1 | U8: 1.0061509 | V8: 1.0181164 | W8: 1.0265938 | X8: 1.0589562 | Y8: 1.0963655 | Z8: 1.1435512 | AA8: 1.1899532 | AB8: 1.2362222 | AC8: 1.2474098
A9: 7 | B9: 水産食料品 | C9: 0.7656154 | D9: 0.84565509 | E9: 0.8914789 | F9: 0.93911566 | G9: 0.93768268 | H9: 0.93245833 | I9: 0.91897436 | J9: 0.90721517 | K9: 0.88985485 | L9: 0.87672727 | M9: 0.89725447 | N9: 0.96067803 | O9: 0.97643238 | P9: 1.0177081 | Q9: 1.0203035 | R9: 1.0015571 | S9: 0.99101709 | T9: 1 | U9: 1.0277863 | V9: 1.0479705 | W9: 1.0594064 | X9: 1.0642434 | Y9: 1.1192745 | Z9: 1.1651325 | AA9: 1.1941606 | AB9: 1.1799957 | AC9: 1.1861935
A10: 8 | B10: 精穀・製粉 | C10: 0.17935539 | D10: 0.33142843 | E10: 0.47447568 | F10: 0.55870329 | G10: 0.61810521 | H10: 0.66522953 | I10: 0.73345904 | J10: 0.76771278 | K10: 0.87177674 | L10: 0.91851759 | M10: 0.94317658 | N10: 1.0007577 | O10: 1.0739719 | P10: 1.0726391 | Q10: 1.0772247 | R10: 1.0251283 | S10: 0.99561852 | T10: 1 | U10: 1.0002832 | V10: 0.96455111 | W10: 0.92658603 | X10: 0.89418572 | Y10: 0.89150059 | Z10: 0.88222265 | AA10: 0.88676706 | AB10: 0.8698804 | AC10: 0.90835558
A11: 9 | B11: その他の食料品 | C11: 1.139247 | D11: 1.0811387 | E11: 1.0382141 | F11: 1.0006709 | G11: 0.96732939 | H11: 0.9370913 | I11: 0.91533311 | J11: 0.90952289 | K11: 0.913331 | L11: 0.91511331 | M11: 0.93251251 | N11: 0.95905572 | O11: 0.98896411 | P11: 1.0135917 | Q11: 1.0086894 | R11: 0.9982382 | S11: 0.98849181 | T11: 1 | U11: 1.0066157 | V11: 0.99926776 | W11: 1.0000256 | X11: 0.99350933 | Y11: 1.0243976 | Z11: 1.0665996 | AA11: 1.1068677 | AB11: 1.1216014 | AC11: 1.1201382
A12: 10 | B12: 飲料 | C12: 0.26344209 | D12: 0.42191323 | E12: 0.52455174 | F12: 0.66747362 | G12: 0.79285354 | H12: 0.86524526 | I12: 0.91421183 | J12: 0.94341159 | K12: 0.97493512 | L12: 0.98164647 | M12: 0.97066717 | N12: 1.0130135 | O12: 1.0161563 | P12: 1.0406486 | Q12: 1.0380746 | R12: 1.0136077 | S12: 0.98968616 | T12: 1 | U12: 1.0054089 | V12: 0.97435232 | W12: 0.9617615 | X12: 0.94244805 | Y12: 0.92232474 | Z12: 0.92765409 | AA12: 0.91774282 | AB12: 0.9310927 | AC12: 0.88899245
A13: 11 | B13: 飼料・有機質肥料 | C13: 0.69417997 | D13: 0.81045148 | E13: 0.95378202 | F13: 1.0400462 | G13: 1.1641521 | H13: 1.2586659 | I13: 1.3253734 | J13: 1.3055655 | K13: 1.2775295 | L13: 1.2528031 | M13: 1.1968974 | N13: 1.1485666 | O13: 1.0674194 | P13: 1.0214137 | Q13: 0.99760834 | R13: 1.019252 | S13: 0.99052007 | T13: 1 | U13: 1.0395756 | V13: 1.0040481 | W13: 0.99066124 | X13: 0.99069822 | Y13: 0.98214299 | Z13: 1.0300147 | AA13: 1.0706092 | AB13: 1.1025903 | AC13: 1.1782012
A14: 12 | B14: たばこ | C14: 0.97034397 | D14: 0.95244228 | E14: 1.0255207 | F14: 0.96636927 | G14: 0.91829743 | H14: 0.89542612 | I14: 0.8838114 | J14: 0.95148649 | K14: 0.95047756 | L14: 0.92376956 | M14: 0.91356955 | N14: 0.93310748 | O14: 0.87665804 | P14: 0.88312199 | Q14: 0.92179238 | R14: 0.93633719 | S14: 0.97918824 | T14: 1 | U14: 0.97472705 | V14: 0.97873091 | W14: 1.0094331 | X14: 1.0170547 | Y14: 0.96207702 | Z14: 0.92639518 | AA14: 0.92768277 | AB14: 0.88684452 | AC14: 0.85244155
... A101: 99 | B101: 会員制団体 | C101: 0.14311848 | D101: 0.22516214 | E101: 0.34571898 | F101: 0.43098881 | G101: 0.50788199 | H101: 0.60682665 | I101: 0.66430563 | J101: 0.70080591 | K101: 0.699551 | L101: 0.75351777 | M101: 0.83741756 | N101: 0.90869635 | O101: 0.926122 | P101: 0.9372841 | Q101: 0.99236381 | R101: 1.0067483 | S101: 1.0042517 | T101: 1 | U101: 0.98854008 | V101: 0.98052771 | W101: 0.98722737 | X101: 0.98113136 | Y101: 0.96709086 | Z101: 0.96356279 | AA101: 0.96339964 | AB101: 0.95367737 | AC101: 0.93912444

Sheet 部門別資本の質指数
A1: 部門別資本の質指数 (2015年=1.000)
A2: JIP部門分類 | C2: 1994 | D2: 1995 | E2: 1996 | F2: 1997 | G2: 1998 | H2: 1999 | I2: 2000 | J2: 2001 | K2: 2002 | L2: 2003 | M2: 2004 | N2: 2005 | O2: 2006 | P2: 2007 | Q2: 2008 | R2: 2009 | S2: 2010 | T2: 2011 | U2: 2012 | V2: 2013 | W2: 2014 | X2: 2015 | Y2: 2016 | Z2: 2017 | AA2: 2018 | AB2: 2019 | AC2: 2020
A3: 1 | B3: 農業 | C3: =部門別資本投入指数!C3/(部門別実質純資本ストック!C3/部門別実質純資本ストック!$X3) -> 0.94911679 | D3: =部門別資本投入指数!D3/(部門別実質純資本ストック!D3/部門別実質純資本ストック!$X3) -> 0.93946857 | E3: =部門別資本投入指数!E3/(部門別実質純資本ストック!E3/部門別実質純資本ストック!$X3) -> 0.93462846 | F3: =部門別資本投入指数!F3/(部門別実質純資本ストック!F3/部門別実質純資本ストック!$X3) -> 0.92837348 | G3: =部門別資本投入指数!G3/(部門別実質純資本ストック!G3/部門別実質純資本ストック!$X3) -> 0.91776953 | H3: =部門別資本投入指数!H3/(部門別実質純資本ストック!H3/部門別実質純資本ストック!$X3) -> 0.91431184 | I3: =部門別資本投入指数!I3/(部門別実質純資本ストック!I3/部門別実質純資本ストック!$X3) -> 0.91283049 | J3: =部門別資本投入指数!J3/(部門別実質純資本ストック!J3/部門別実質純資本ストック!$X3) -> 0.90995449 | ... AC3: =部門別資本投入指数!AC3/(部門別実質純資本ストック!AC3/部門別実質純資本ストック!$X3) -> 0.9191024
A4: 2 | B4: 農業サービス | C4: =部門別資本投入指数!C4/(部門別実質純資本ストック!C4/部門別実質純資本ストック!$X4) -> 0.83077716 | D4: =部門別資本投入指数!D4/(部門別実質純資本ストック!D4/部門別実質純資本ストック!$X4) -> 0.86965714 | E4: =部門別資本投入指数!E4/(部門別実質純資本ストック!E4/部門別実質純資本ストック!$X4) -> 0.89988827 | F4: =部門別資本投入指数!F4/(部門別実質純資本ストック!F4/部門別実質純資本ストック!$X4) -> 0.92545467 | G4: =部門別資本投入指数!G4/(部門別実質純資本ストック!G4/部門別実質純資本ストック!$X4) -> 0.9504394 | H4: =部門別資本投入指数!H4/(部門別実質純資本ストック!H4/部門別実質純資本ストック!$X4) -> 0.96072331 | I4: =部門別資本投入指数!I4/(部門別実質純資本ストック!I4/部門別実質純資本ストック!$X4) -> 0.95285068 | J4: =部門別資本投入指数!J4/(部門別実質純資本ストック!J4/部門別実質純資本ストック!$X4) -> 0.94612662 | ... AC4: =部門別資本投入指数!AC4/(部門別実質純資本ストック!AC4/部門別実質純資本ストック!$X4) -> 0.89128709
A5: 3 | B5: 林業 | C5: =部門別資本投入指数!C5/(部門別実質純資本ストック!C5/部門別実質純資本ストック!$X5) -> 0.94617824 | D5: =部門別資本投入指数!D5/(部門別実質純資本ストック!D5/部門別実質純資本ストック!$X5) -> 0.95029284 | E5: =部門別資本投入指数!E5/(部門別実質純資本ストック!E5/部門別実質純資本ストック!$X5) -> 0.94414554 | F5: =部門別資本投入指数!F5/(部門別実質純資本ストック!F5/部門別実質純資本ストック!$X5) -> 0.94701397 | G5: =部門別資本投入指数!G5/(部門別実質純資本ストック!G5/部門別実質純資本ストック!$X5) -> 0.92820919 | H5: =部門別資本投入指数!H5/(部門別実質純資本ストック!H5/部門別実質純資本ストック!$X5) -> 0.93618769 | I5: =部門別資本投入指数!I5/(部門別実質純資本ストック!I5/部門別実質純資本ストック!$X5) -> 0.92622544 | J5: =部門別資本投入指数!J5/(部門別実質純資本ストック!J5/部門別実質純資本ストック!$X5) -> 0.92936008 | ... AC5: =部門別資本投入指数!AC5/(部門別実質純資本ストック!AC5/部門別実質純資本ストック!$X5) -> 0.90319161
A6: 4 | B6: 漁業 | C6: =部門別資本投入指数!C6/(部門別実質純資本ストック!C6/部門別実質純資本ストック!$X6) -> 0.87995897 | D6: =部門別資本投入指数!D6/(部門別実質純資本ストック!D6/部門別実質純資本ストック!$X6) -> 0.87292281 | E6: =部門別資本投入指数!E6/(部門別実質純資本ストック!E6/部門別実質純資本ストック!$X6) -> 0.87112849 | F6: =部門別資本投入指数!F6/(部門別実質純資本ストック!F6/部門別実質純資本ストック!$X6) -> 0.87119217 | G6: =部門別資本投入指数!G6/(部門別実質純資本ストック!G6/部門別実質純資本ストック!$X6) -> 0.8632755 | H6: =部門別資本投入指数!H6/(部門別実質純資本ストック!H6/部門別実質純資本ストック!$X6) -> 0.8521843 | I6: =部門別資本投入指数!I6/(部門別実質純資本ストック!I6/部門別実質純資本ストック!$X6) -> 0.8636595 | J6: =部門別資本投入指数!J6/(部門別実質純資本ストック!J6/部門別実質純資本ストック!$X6) -> 0.87683772 | ... AC6: =部門別資本投入指数!AC6/(部門別実質純資本ストック!AC6/部門別実質純資本ストック!$X6) -> 0.93132374
A7: 5 | B7: 鉱業 | C7: =部門別資本投入指数!C7/(部門別実質純資本ストック!C7/部門別実質純資本ストック!$X7) -> 1.2470524 | D7: =部門別資本投入指数!D7/(部門別実質純資本ストック!D7/部門別実質純資本ストック!$X7) -> 1.2544909 | E7: =部門別資本投入指数!E7/(部門別実質純資本ストック!E7/部門別実質純資本ストック!$X7) -> 1.2471454 | F7: =部門別資本投入指数!F7/(部門別実質純資本ストック!F7/部門別実質純資本ストック!$X7) -> 1.2386235 | G7: =部門別資本投入指数!G7/(部門別実質純資本ストック!G7/部門別実質純資本ストック!$X7) -> 1.2290227 | H7: =部門別資本投入指数!H7/(部門別実質純資本ストック!H7/部門別実質純資本ストック!$X7) -> 1.2122498 | I7: =部門別資本投入指数!I7/(部門別実質純資本ストック!I7/部門別実質純資本ストック!$X7) -> 1.2157475 | J7: =部門別資本投入指数!J7/(部門別実質純資本ストック!J7/部門別実質純資本ストック!$X7) -> 1.2067865 | ... AC7: =部門別資本投入指数!AC7/(部門別実質純資本ストック!AC7/部門別実質純資本ストック!$X7) -> 0.98804587
A8: 6 | B8: 畜産食料品 | C8: =部門別資本投入指数!C8/(部門別実質純資本ストック!C8/部門別実質純資本ストック!$X8) -> 1.0011177 | D8: =部門別資本投入指数!D8/(部門別実質純資本ストック!D8/部門別実質純資本ストック!$X8) -> 1.0157343 | E8: =部門別資本投入指数!E8/(部門別実質純資本ストック!E8/部門別実質純資本ストック!$X8) -> 1.0235205 | F8: =部門別資本投入指数!F8/(部門別実質純資本ストック!F8/部門別実質純資本ストック!$X8) -> 1.0255713 | G8: =部門別資本投入指数!G8/(部門別実質純資本ストック!G8/部門別実質純資本ストック!$X8) -> 1.0247254 | H8: =部門別資本投入指数!H8/(部門別実質純資本ストック!H8/部門別実質純資本ストック!$X8) -> 1.0323545 | I8: =部門別資本投入指数!I8/(部門別実質純資本ストック!I8/部門別実質純資本ストック!$X8) -> 1.0288878 | J8: =部門別資本投入指数!J8/(部門別実質純資本ストック!J8/部門別実質純資本ストック!$X8) -> 1.0393859 | ... AC8: =部門別資本投入指数!AC8/(部門別実質純資本ストック!AC8/部門別実質純資本ストック!$X8) -> 1.0830528
A9: 7 | B9: 水産食料品 | C9: =部門別資本投入指数!C9/(部門別実質純資本ストック!C9/部門別実質純資本ストック!$X9) -> 1.0348544 | D9: =部門別資本投入指数!D9/(部門別実質純資本ストック!D9/部門別実質純資本ストック!$X9) -> 1.0633686 | E9: =部門別資本投入指数!E9/(部門別実質純資本ストック!E9/部門別実質純資本ストック!$X9) -> 1.0764511 | F9: =部門別資本投入指数!F9/(部門別実質純資本ストック!F9/部門別実質純資本ストック!$X9) -> 1.0859957 | G9: =部門別資本投入指数!G9/(部門別実質純資本ストック!G9/部門別実質純資本ストック!$X9) -> 1.0709703 | H9: =部門別資本投入指数!H9/(部門別実質純資本ストック!H9/部門別実質純資本ストック!$X9) -> 1.0609227 | I9: =部門別資本投入指数!I9/(部門別実質純資本ストック!I9/部門別実質純資本ストック!$X9) -> 1.0426283 | J9: =部門別資本投入指数!J9/(部門別実質純資本ストック!J9/部門別実質純資本ストック!$X9) -> 1.033028 | ... AC9: =部門別資本投入指数!AC9/(部門別実質純資本ストック!AC9/部門別実質純資本ストック!$X9) -> 1.0818241
A10: 8 | B10: 精穀・製粉 | C10: =部門別資本投入指数!C10/(部門別実質純資本ストック!C10/部門別実質純資本ストック!$X10) -> 0.69023345 | D10: =部門別資本投入指数!D10/(部門別実質純資本ストック!D10/部門別実質純資本ストック!$X10) -> 0.88559659 | E10: =部門別資本投入指数!E10/(部門別実質純資本ストック!E10/部門別実質純資本ストック!$X10) -> 0.94600652 | F10: =部門別資本投入指数!F10/(部門別実質純資本ストック!F10/部門別実質純資本ストック!$X10) -> 0.958203 | G10: =部門別資本投入指数!G10/(部門別実質純資本ストック!G10/部門別実質純資本ストック!$X10) -> 0.95283412 | H10: =部門別資本投入指数!H10/(部門別実質純資本ストック!H10/部門別実質純資本ストック!$X10) -> 0.9520953 | I10: =部門別資本投入指数!I10/(部門別実質純資本ストック!I10/部門別実質純資本ストック!$X10) -> 0.94838821 | J10: =部門別資本投入指数!J10/(部門別実質純資本ストック!J10/部門別実質純資本ストック!$X10) -> 0.94391037 | ... AC10: =部門別資本投入指数!AC10/(部門別実質純資本ストック!AC10/部門別実質純資本ストック!$X10) -> 0.87956655
A11: 9 | B11: その他の食料品 | C11: =部門別資本投入指数!C11/(部門別実質純資本ストック!C11/部門別実質純資本ストック!$X11) -> 1.0357286 | D11: =部門別資本投入指数!D11/(部門別実質純資本ストック!D11/部門別実質純資本ストック!$X11) -> 1.0189561 | E11: =部門別資本投入指数!E11/(部門別実質純資本ストック!E11/部門別実質純資本ストック!$X11) -> 1.0074768 | F11: =部門別資本投入指数!F11/(部門別実質純資本ストック!F11/部門別実質純資本ストック!$X11) -> 0.99653129 | G11: =部門別資本投入指数!G11/(部門別実質純資本ストック!G11/部門別実質純資本ストック!$X11) -> 0.98237358 | H11: =部門別資本投入指数!H11/(部門別実質純資本ストック!H11/部門別実質純資本ストック!$X11) -> 0.97206602 | I11: =部門別資本投入指数!I11/(部門別実質純資本ストック!I11/部門別実質純資本ストック!$X11) -> 0.96054873 | J11: =部門別資本投入指数!J11/(部門別実質純資本ストック!J11/部門別実質純資本ストック!$X11) -> 0.95956529 | ... AC11: =部門別資本投入指数!AC11/(部門別実質純資本ストック!AC11/部門別実質純資本ストック!$X11) -> 1.0174441
A12: 10 | B12: 飲料 | C12: =部門別資本投入指数!C12/(部門別実質純資本ストック!C12/部門別実質純資本ストック!$X12) -> 0.89990632 | D12: =部門別資本投入指数!D12/(部門別実質純資本ストック!D12/部門別実質純資本ストック!$X12) -> 1.0417715 | E12: =部門別資本投入指数!E12/(部門別実質純資本ストック!E12/部門別実質純資本ストック!$X12) -> 1.0608074 | F12: =部門別資本投入指数!F12/(部門別実質純資本ストック!F12/部門別実質純資本ストック!$X12) -> 1.0737028 | G12: =部門別資本投入指数!G12/(部門別実質純資本ストック!G12/部門別実質純資本ストック!$X12) -> 1.0632841 | H12: =部門別資本投入指数!H12/(部門別実質純資本ストック!H12/部門別実質純資本ストック!$X12) -> 1.0543299 | I12: =部門別資本投入指数!I12/(部門別実質純資本ストック!I12/部門別実質純資本ストック!$X12) -> 1.0325362 | J12: =部門別資本投入指数!J12/(部門別実質純資本ストック!J12/部門別実質純資本ストック!$X12) -> 1.0225853 | ... AC12: =部門別資本投入指数!AC12/(部門別実質純資本ストック!AC12/部門別実質純資本ストック!$X12) -> 0.92041723
A13: 11 | B13: 飼料・有機質肥料 | C13: =部門別資本投入指数!C13/(部門別実質純資本ストック!C13/部門別実質純資本ストック!$X13) -> 0.98066857 | D13: =部門別資本投入指数!D13/(部門別実質純資本ストック!D13/部門別実質純資本ストック!$X13) -> 1.0155585 | E13: =部門別資本投入指数!E13/(部門別実質純資本ストック!E13/部門別実質純資本ストック!$X13) -> 1.0469055 | F13: =部門別資本投入指数!F13/(部門別実質純資本ストック!F13/部門別実質純資本ストック!$X13) -> 1.0577383 | G13: =部門別資本投入指数!G13/(部門別実質純資本ストック!G13/部門別実質純資本ストック!$X13) -> 1.0655398 | H13: =部門別資本投入指数!H13/(部門別実質純資本ストック!H13/部門別実質純資本ストック!$X13) -> 1.075252 | I13: =部門別資本投入指数!I13/(部門別実質純資本ストック!I13/部門別実質純資本ストック!$X13) -> 1.0744068 | J13: =部門別資本投入指数!J13/(部門別実質純資本ストック!J13/部門別実質純資本ストック!$X13) -> 1.0680481 | ... AC13: =部門別資本投入指数!AC13/(部門別実質純資本ストック!AC13/部門別実質純資本ストック!$X13) -> 0.99346941
A14: 12 | B14: たばこ | C14: =部門別資本投入指数!C14/(部門別実質純資本ストック!C14/部門別実質純資本ストック!$X14) -> 1.1666103 | D14: =部門別資本投入指数!D14/(部門別実質純資本ストック!D14/部門別実質純資本ストック!$X14) -> 1.1652313 | E14: =部門別資本投入指数!E14/(部門別実質純資本ストック!E14/部門別実質純資本ストック!$X14) -> 1.1939698 | F14: =部門別資本投入指数!F14/(部門別実質純資本ストック!F14/部門別実質純資本ストック!$X14) -> 1.1545866 | G14: =部門別資本投入指数!G14/(部門別実質純資本ストック!G14/部門別実質純資本ストック!$X14) -> 1.1108844 | H14: =部門別資本投入指数!H14/(部門別実質純資本ストック!H14/部門別実質純資本ストック!$X14) -> 1.0772077 | I14: =部門別資本投入指数!I14/(部門別実質純資本ストック!I14/部門別実質純資本ストック!$X14) -> 1.0303817 | J14: =部門別資本投入指数!J14/(部門別実質純資本ストック!J14/部門別実質純資本ストック!$X14) -> 1.0102945 | ... AC14: =部門別資本投入指数!AC14/(部門別実質純資本ストック!AC14/部門別実質純資本ストック!$X14) -> 0.99251384
... A96: 94 | B96: 社会保険・社会福祉 | C96: =部門別資本投入指数!C96/(部門別実質純資本ストック!C96/部門別実質純資本ストック!$X96) -> 1.5344961 | D96: =部門別資本投入指数!D96/(部門別実質純資本ストック!D96/部門別実質純資本ストック!$X96) -> 1.485498 | E96: =部門別資本投入指数!E96/(部門別実質純資本ストック!E96/部門別実質純資本ストック!$X96) -> 1.4766794 | F96: =部門別資本投入指数!F96/(部門別実質純資本ストック!F96/部門別実質純資本ストック!$X96) -> 1.4744627 | G96: =部門別資本投入指数!G96/(部門別実質純資本ストック!G96/部門別実質純資本ストック!$X96) -> 1.4675195 | H96: =部門別資本投入指数!H96/(部門別実質純資本ストック!H96/部門別実質純資本ストック!$X96) -> 1.4918247 | I96: =部門別資本投入指数!I96/(部門別実質純資本ストック!I96/部門別実質純資本ストック!$X96) -> 1.4873008 | J96: =部門別資本投入指数!J96/(部門別実質純資本ストック!J96/部門別実質純資本ストック!$X96) -> 1.5024174 | ... AC96: =部門別資本投入指数!AC96/(部門別実質純資本ストック!AC96/部門別実質純資本ストック!$X96) -> 1.4165384
A97: 95 | B97: 介護 | I97: =部門別資本投入指数!I97/(部門別実質純資本ストック!I97/部門別実質純資本ストック!$X97) -> 1.502606 | J97: =部門別資本投入指数!J97/(部門別実質純資本ストック!J97/部門別実質純資本ストック!$X97) -> 1.5487533 | K97: =部門別資本投入指数!K97/(部門別実質純資本ストック!K97/部門別実質純資本ストック!$X97) -> 1.5480601 | L97: =部門別資本投入指数!L97/(部門別実質純資本ストック!L97/部門別実質純資本ストック!$X97) -> 1.5494464 | M97: =部門別資本投入指数!M97/(部門別実質純資本ストック!M97/部門別実質純資本ストック!$X97) -> 1.5516706 | N97: =部門別資本投入指数!N97/(部門別実質純資本ストック!N97/部門別実質純資本ストック!$X97) -> 1.5632192 | O97: =部門別資本投入指数!O97/(部門別実質純資本ストック!O97/部門別実質純資本ストック!$X97) -> 1.5632442 | P97: =部門別資本投入指数!P97/(部門別実質純資本ストック!P97/部門別実質純資本ストック!$X97) -> 1.5612325 | ... AC97: =部門別資本投入指数!AC97/(部門別実質純資本ストック!AC97/部門別実質純資本ストック!$X97) -> 1.4612128
A98: 96 | B98: 娯楽業 | C98: =部門別資本投入指数!C98/(部門別実質純資本ストック!C98/部門別実質純資本ストック!$X98) -> 0.75828562 | D98: =部門別資本投入指数!D98/(部門別実質純資本ストック!D98/部門別実質純資本ストック!$X98) -> 0.75781041 | E98: =部門別資本投入指数!E98/(部門別実質純資本ストック!E98/部門別実質純資本ストック!$X98) -> 0.77731772 | F98: =部門別資本投入指数!F98/(部門別実質純資本ストック!F98/部門別実質純資本ストック!$X98) -> 0.79360294 | G98: =部門別資本投入指数!G98/(部門別実質純資本ストック!G98/部門別実質純資本ストック!$X98) -> 0.8011759 | H98: =部門別資本投入指数!H98/(部門別実質純資本ストック!H98/部門別実質純資本ストック!$X98) -> 0.81280481 | I98: =部門別資本投入指数!I98/(部門別実質純資本ストック!I98/部門別実質純資本ストック!$X98) -> 0.82254313 | J98: =部門別資本投入指数!J98/(部門別実質純資本ストック!J98/部門別実質純資本ストック!$X98) -> 0.84008366 | ... AC98: =部門別資本投入指数!AC98/(部門別実質純資本ストック!AC98/部門別実質純資本ストック!$X98) -> 0.92320341
A99: 97 | B99: 洗濯・理容・美容・浴場業 | C99: =部門別資本投入指数!C99/(部門別実質純資本ストック!C99/部門別実質純資本ストック!$X99) -> 0.52696257 | D99: =部門別資本投入指数!D99/(部門別実質純資本ストック!D99/部門別実質純資本ストック!$X99) -> 0.56424127 | E99: =部門別資本投入指数!E99/(部門別実質純資本ストック!E99/部門別実質純資本ストック!$X99) -> 0.64936005 | F99: =部門別資本投入指数!F99/(部門別実質純資本ストック!F99/部門別実質純資本ストック!$X99) -> 0.68492916 | G99: =部門別資本投入指数!G99/(部門別実質純資本ストック!G99/部門別実質純資本ストック!$X99) -> 0.68154903 | H99: =部門別資本投入指数!H99/(部門別実質純資本ストック!H99/部門別実質純資本ストック!$X99) -> 0.70971768 | I99: =部門別資本投入指数!I99/(部門別実質純資本ストック!I99/部門別実質純資本ストック!$X99) -> 0.7388506 | J99: =部門別資本投入指数!J99/(部門別実質純資本ストック!J99/部門別実質純資本ストック!$X99) -> 0.7594901 | ... AC99: =部門別資本投入指数!AC99/(部門別実質純資本ストック!AC99/部門別実質純資本ストック!$X99) -> 0.92733696
A100: 98 | B100: その他の対個人サービス | C100: =部門別資本投入指数!C100/(部門別実質純資本ストック!C100/部門別実質純資本ストック!$X100) -> 0.72212019 | D100: =部門別資本投入指数!D100/(部門別実質純資本ストック!D100/部門別実質純資本ストック!$X100) -> 0.74420122 | E100: =部門別資本投入指数!E100/(部門別実質純資本ストック!E100/部門別実質純資本ストック!$X100) -> 0.73183408 | F100: =部門別資本投入指数!F100/(部門別実質純資本ストック!F100/部門別実質純資本ストック!$X100) -> 0.76692877 | G100: =部門別資本投入指数!G100/(部門別実質純資本ストック!G100/部門別実質純資本ストック!$X100) -> 0.79530088 | H100: =部門別資本投入指数!H100/(部門別実質純資本ストック!H100/部門別実質純資本ストック!$X100) -> 0.8420084 | I100: =部門別資本投入指数!I100/(部門別実質純資本ストック!I100/部門別実質純資本ストック!$X100) -> 0.88261378 | J100: =部門別資本投入指数!J100/(部門別実質純資本ストック!J100/部門別実質純資本ストック!$X100) -> 0.90556636 | ... AC100: =部門別資本投入指数!AC100/(部門別実質純資本ストック!AC100/部門別実質純資本ストック!$X100) -> 1.0321958
A101: 99 | B101: 会員制団体 | C101: =部門別資本投入指数!C101/(部門別実質純資本ストック!C101/部門別実質純資本ストック!$X101) -> 1.2964121 | D101: =部門別資本投入指数!D101/(部門別実質純資本ストック!D101/部門別実質純資本ストック!$X101) -> 1.1542157 | E101: =部門別資本投入指数!E101/(部門別実質純資本ストック!E101/部門別実質純資本ストック!$X101) -> 1.1167285 | F101: =部門別資本投入指数!F101/(部門別実質純資本ストック!F101/部門別実質純資本ストック!$X101) -> 1.0793739 | G101: =部門別資本投入指数!G101/(部門別実質純資本ストック!G101/部門別実質純資本ストック!$X101) -> 1.0498398 | H101: =部門別資本投入指数!H101/(部門別実質純資本ストック!H101/部門別実質純資本ストック!$X101) -> 1.032868 | I101: =部門別資本投入指数!I101/(部門別実質純資本ストック!I101/部門別実質純資本ストック!$X101) -> 1.0115662 | J101: =部門別資本投入指数!J101/(部門別実質純資本ストック!J101/部門別実質純資本ストック!$X101) -> 0.99692595 | ... AC101: =部門別資本投入指数!AC101/(部門別実質純資本ストック!AC101/部門別実質純資本ストック!$X101) -> 0.9784848

Sheet 部門別名目純資本ストック
A1: 部門別名目純資本ストック (100万円)
A2: JIP部門分類 | C2: 1994 | D2: 1995 | E2: 1996 | F2: 1997 | G2: 1998 | H2: 1999 | I2: 2000 | J2: 2001 | K2: 2002 | L2: 2003 | M2: 2004 | N2: 2005 | O2: 2006 | P2: 2007 | Q2: 2008 | R2: 2009 | S2: 2010 | T2: 2011 | U2: 2012 | V2: 2013 | W2: 2014 | X2: 2015 | Y2: 2016 | Z2: 2017 | AA2: 2018 | AB2: 2019 | AC2: 2020
A3: 1 | B3: 農業 | C3: 25751659 | D3: 25051264 | E3: 24370898 | F3: 23878671 | G3: 23346191 | H3: 22587072 | I3: 21599123 | J3: 20445866 | K3: 19198786 | L3: 18403243 | M3: 17684830 | N3: 17194619 | O3: 16470589 | P3: 15733680 | Q3: 15192320 | R3: 14216319 | S3: 13504599 | T3: 12931164 | U3: 12461006 | V3: 12375541 | W3: 12286881 | X3: 12225560 | Y3: 11902508 | Z3: 12196981 | AA3: 11942367 | AB3: 11704282 | AC3: 11365499
A4: 2 | B4: 農業サービス | C4: 2660764.6 | D4: 2543437.7 | E4: 2401565.8 | F4: 2283689 | G4: 2167833.9 | H4: 2029477.3 | I4: 1875933.2 | J4: 1716000.3 | K4: 1564733.6 | L4: 1442695.2 | M4: 1330444.9 | N4: 1248464.9 | O4: 1171471.5 | P4: 1103201.5 | Q4: 1049291.5 | R4: 968133.26 | S4: 895885.81 | T4: 856409.04 | U4: 826860.32 | V4: 812180.26 | W4: 782988.19 | X4: 769316.88 | Y4: 720279.42 | Z4: 687987.02 | AA4: 679151.55 | AB4: 646564.39 | AC4: 609675.44
A5: 3 | B5: 林業 | C5: 649228.23 | D5: 626429.58 | E5: 595461.05 | F5: 593820.26 | G5: 548233.78 | H5: 530409.2 | I5: 496171.98 | J5: 507528.92 | K5: 515681.52 | L5: 505618.13 | M5: 518107.95 | N5: 516988.22 | O5: 499892.58 | P5: 493601.05 | Q5: 486346.06 | R5: 459373.91 | S5: 439444.87 | T5: 424529.09 | U5: 411739.68 | V5: 408064.84 | W5: 395516.64 | X5: 393576.78 | Y5: 380971.32 | Z5: 386821.24 | AA5: 407488.86 | AB5: 401468.91 | AC5: 385246.92
A6: 4 | B6: 漁業 | C6: 3484660.3 | D6: 3621028.1 | E6: 3638869.9 | F6: 3659216 | G6: 3438427.3 | H6: 3095264.4 | I6: 3022327.6 | J6: 2971490.4 | K6: 2800634.8 | L6: 2563996 | M6: 2483054 | N6: 2404717.1 | O6: 2294460.2 | P6: 2152804.8 | Q6: 2069956.1 | R6: 1930060 | S6: 1833079.2 | T6: 1765654.9 | U6: 1721534.8 | V6: 1707505.4 | W6: 1641392 | X6: 1631352.4 | Y6: 1571260.6 | Z6: 1594047.3 | AA6: 1685628 | AB6: 1647087.6 | AC6: 1567238.5
A7: 5 | B7: 鉱業 | C7: 3332030.1 | D7: 3287607.5 | E7: 3186946.3 | F7: 3120750.3 | G7: 3000650.6 | H7: 2840071.3 | I7: 2774648.6 | J7: 2664117.4 | K7: 2593918.9 | L7: 2494910.9 | M7: 2417511.4 | N7: 2375297 | O7: 2363095.2 | P7: 2376828.8 | Q7: 2457880.1 | R7: 2377465.2 | S7: 2320371.7 | T7: 2303516.7 | U7: 2275670.6 | V7: 2344866.1 | W7: 2463615 | X7: 2537280.6 | Y7: 2544895.2 | Z7: 2666948.4 | AA7: 2676957.5 | AB7: 2667750.7 | AC7: 2611576.3
A8: 6 | B8: 畜産食料品 | C8: 1859945.4 | D8: 1951041.7 | E8: 2011401.2 | F8: 2070453.4 | G8: 2119634.4 | H8: 2173906.7 | I8: 2256717 | J8: 2340896.4 | K8: 2387049.2 | L8: 2403503.7 | M8: 2440303.3 | N8: 2495389.1 | O8: 2636487.5 | P8: 2732994.6 | Q8: 2779457.8 | R8: 2693538.1 | S8: 2662798.5 | T8: 2705535.3 | U8: 2726959.7 | V8: 2788000.4 | W8: 2871910.7 | X8: 2970904.7 | Y8: 3038797.2 | Z8: 3177633.5 | AA8: 3322801.5 | AB8: 3465501.9 | AC8: 3506174.4
A9: 7 | B9: 水産食料品 | C9: 796705.72 | D9: 858250.19 | E9: 893888.63 | F9: 940680.01 | G9: 937008.42 | H9: 922310.55 | I9: 918306.05 | J9: 900468.39 | K9: 875550.05 | L9: 858884.92 | M9: 868327.91 | N9: 909896.46 | O9: 933735.79 | P9: 969053.76 | Q9: 992832.39 | R9: 962461.54 | S9: 950175.72 | T9: 967682.71 | U9: 988991.45 | V9: 1018198.2 | W9: 1053692.8 | X9: 1071373.8 | Y9: 1105957.4 | Z9: 1152736 | AA9: 1190309.9 | AB9: 1198444 | AC9: 1207718.7
A10: 8 | B10: 精穀・製粉 | C10: 81227.947 | D10: 118404.1 | E10: 159715.35 | F10: 186486.34 | G10: 204225.01 | H10: 216186.19 | I10: 237979.33 | J10: 246243.39 | K10: 270681.61 | L10: 281242.86 | M10: 286561.54 | N10: 300735.25 | O10: 325213.7 | P10: 327936.11 | Q10: 335853.17 | R10: 316643.43 | S10: 310045.71 | T10: 316717.35 | U10: 319030.94 | V10: 314097.36 | W10: 312004.98 | X10: 307633.58 | Y10: 306795.43 | Z10: 308976.78 | AA10: 315291.18 | AB10: 314661.01 | AC10: 326116.37
A11: 9 | B11: その他の食料品 | C11: 10471756 | D11: 10028659 | E11: 9708270.6 | F11: 9508245.6 | G11: 9183815.1 | H11: 8825063.7 | I11: 8678197.3 | J11: 8513382.8 | K11: 8391337.2 | L11: 8314553 | M11: 8372891.3 | N11: 8536425 | O11: 8836214.5 | P11: 9048422.6 | Q11: 9205124.7 | R11: 8943213.4 | S11: 8832509.7 | T11: 9001085.5 | U11: 9051177.5 | V11: 9112369.4 | W11: 9334117.4 | X11: 9394727.7 | Y11: 9555462.2 | Z11: 9952865.5 | AA11: 10362362 | AB11: 10599568 | AC11: 10633477
A12: 10 | B12: 飲料 | C12: 1451818.3 | D12: 2015247.8 | E12: 2457000.4 | F12: 3108725.5 | G12: 3678919.9 | H12: 3967447 | I12: 4232279.9 | J12: 4334890.4 | K12: 4427627.9 | L12: 4442749.1 | M12: 4405703.2 | N12: 4580476.9 | O12: 4667864.2 | P12: 4802765.4 | Q12: 4901180.2 | R12: 4736071.9 | S12: 4636140.3 | T12: 4730350.9 | U12: 4773120.7 | V12: 4720513.8 | W12: 4783038 | X12: 4766437.1 | Y12: 4673738.3 | Z12: 4748157 | AA12: 4769058.8 | AB12: 4873184.3 | AC12: 4726489.3
A13: 11 | B13: 飼料・有機質肥料 | C13: 320149.31 | D13: 363527.27 | E13: 417375.21 | F13: 453589.83 | G13: 500063.06 | H13: 527372.52 | I13: 551509.54 | J13: 537884.47 | K13: 517446.53 | L13: 502700.35 | M13: 483011.48 | N13: 469617.82 | O13: 445568.47 | P13: 429096.46 | Q13: 427183.27 | R13: 424750.59 | S13: 414288.14 | T13: 422899.48 | U13: 439382.03 | V13: 432460.07 | W13: 438734.18 | X13: 444393.69 | Y13: 442469.9 | Z13: 467812.12 | AA13: 490998.85 | AB13: 510085.06 | AC13: 539476.61
A14: 12 | B14: たばこ | C14: 1589710 | D14: 1554160.2 | E14: 1639008.3 | F14: 1593362.6 | G14: 1539797.4 | H14: 1512981.2 | I14: 1546682.5 | J14: 1672452.2 | K14: 1686088.9 | L14: 1674353.2 | M14: 1701578.9 | N14: 1795275.4 | O14: 1757648 | P14: 1790589.6 | Q14: 1886140.5 | R14: 1841776.4 | S14: 1856466.8 | T14: 1866707.4 | U14: 1816676.6 | V14: 1815601.1 | W14: 1867192.8 | X14: 1869862.2 | Y14: 1781774.4 | Z14: 1747592.5 | AA14: 1753807.6 | AB14: 1714323.6 | AC14: 1662433.4
... A101: 99 | B101: 会員制団体 | C101: 637747.7 | D101: 1096713.4 | E101: 1731142.9 | F101: 2234966.2 | G101: 2646837.3 | H101: 3146033 | I101: 3497607.2 | J101: 3685512.7 | K101: 3674184.4 | L101: 3941941.7 | M101: 4376144.6 | N101: 4764909.7 | O101: 4949270.3 | P101: 5083372 | Q101: 5561456.2 | R101: 5549380.6 | S101: 5511624.4 | T101: 5595107.3 | U101: 5483536.9 | V101: 5528005.8 | W101: 5698148.5 | X101: 5711955 | Y101: 5634401 | Z101: 5716055.2 | AA101: 5805344.2 | AB101: 5819767.7 | AC101: 5723281.5

Sheet 部門別実質純資本ストック
A1: 部門別実質純資本ストック (100万円、2015年価格)
A2: JIP部門分類 | C2: 1994 | D2: 1995 | E2: 1996 | F2: 1997 | G2: 1998 | H2: 1999 | I2: 2000 | J2: 2001 | K2: 2002 | L2: 2003 | M2: 2004 | N2: 2005 | O2: 2006 | P2: 2007 | Q2: 2008 | R2: 2009 | S2: 2010 | T2: 2011 | U2: 2012 | V2: 2013 | W2: 2014 | X2: 2015 | Y2: 2016 | Z2: 2017 | AA2: 2018 | AB2: 2019 | AC2: 2020
A3: 1 | B3: 農業 | C3: 25111938 | D3: 24573565 | E3: 23922552 | F3: 23381864 | G3: 23232087 | H3: 22937306 | I3: 22091848 | J3: 21174058 | K3: 20293662 | L3: 19606630 | M3: 18888829 | N3: 18252199 | O3: 17339412 | P3: 16488613 | Q3: 15737683 | R3: 14962929 | S3: 14281388 | T3: 13574862 | U3: 13087232 | V3: 12802034 | W3: 12456784 | X3: 12225560 | Y3: 11858338 | Z3: 12045940 | AA3: 11682627 | AB3: 11348254 | AC3: 11099069
A4: 2 | B4: 農業サービス | C4: 2466697.6 | D4: 2337733.9 | E4: 2197838.5 | F4: 2070972.1 | G4: 1974685.1 | H4: 1877795.9 | I4: 1763741.1 | J4: 1650520.5 | K4: 1543152.6 | L4: 1455657.2 | M4: 1362830.1 | N4: 1282686.6 | O4: 1199331.4 | P4: 1125999.3 | Q4: 1057247.5 | R4: 993816.33 | S4: 929926.54 | T4: 884588.37 | U4: 854738.01 | V4: 831978.07 | W4: 788986.4 | X4: 769316.88 | Y4: 726819.01 | Z4: 689868.68 | AA4: 675840.49 | AB4: 637718.47 | AC4: 601638.53
A5: 3 | B5: 林業 | C5: 656480.71 | D5: 636050 | E5: 604175.24 | F5: 596111.31 | G5: 559922.17 | H5: 550289.52 | I5: 518022.89 | J5: 536688.3 | K5: 553268.84 | L5: 547455.92 | M5: 561883.07 | N5: 556679.69 | O5: 533133.75 | P5: 521150.69 | Q5: 501696.95 | R5: 482541.31 | S5: 464596.8 | T5: 442119.58 | U5: 428996.29 | V5: 419754.07 | W5: 398789.52 | X5: 393576.78 | Y5: 383665.04 | Z5: 385767.87 | AA5: 402114.9 | AB5: 391425.65 | AC5: 375174.23
A6: 4 | B6: 漁業 | C6: 3542706.3 | D6: 3677476.2 | E6: 3673006 | F6: 3656428.1 | G6: 3480623.1 | H6: 3195848.5 | I6: 3126141.7 | J6: 3095604.5 | K6: 2951806.9 | L6: 2724307 | M6: 2641386.8 | N6: 2540695.6 | O6: 2404232.1 | P6: 2240085 | Q6: 2114307.2 | R6: 2002902.2 | S6: 1916386 | T6: 1831334.8 | U6: 1785238 | V6: 1751132.3 | W6: 1654440.1 | X6: 1631352.4 | Y6: 1584934.9 | Z6: 1597097 | AA6: 1676933.1 | AB6: 1623929.2 | AC6: 1544924
A7: 5 | B7: 鉱業 | C7: 3415000 | D7: 3375101.4 | E7: 3272259.6 | F7: 3179295.8 | G7: 3100237.9 | H7: 2993486.5 | I7: 2930525.6 | J7: 2851166.9 | K7: 2815702.7 | L7: 2724505.9 | M7: 2640311.8 | N7: 2572369.8 | O7: 2528777.7 | P7: 2513839.4 | Q7: 2514401.3 | R7: 2487117.2 | S7: 2440575.8 | T7: 2410001.6 | U7: 2379596.5 | V7: 2426560.1 | W7: 2486625.3 | X7: 2537280.6 | Y7: 2563871.1 | Z7: 2653369.6 | AA7: 2625057.1 | AB7: 2575616.6 | AC7: 2507526.7
A8: 6 | B8: 畜産食料品 | C8: 1827073.4 | D8: 1922255.8 | E8: 1986379.8 | F8: 2034422.5 | G8: 2111989.1 | H8: 2201274.6 | I8: 2297332.3 | J8: 2414286.5 | K8: 2498384 | L8: 2537720.7 | M8: 2580293.3 | N8: 2618156.6 | O8: 2736242.2 | P8: 2813892.7 | Q8: 2802640.7 | R8: 2782921 | S8: 2769898.4 | T8: 2803797.3 | U8: 2828958 | V8: 2867588.2 | W8: 2894126.5 | X8: 2970904.7 | Y8: 3064191.8 | Z8: 3173885.6 | AA8: 3282470.8 | AB8: 3387801.5 | AC8: 3421749.8
A9: 7 | B9: 水産食料品 | C9: 792633.52 | D9: 852021.31 | E9: 887274.05 | F9: 926471.31 | G9: 938035.95 | H9: 941643.9 | I9: 944310.68 | J9: 940890.78 | K9: 930444.11 | L9: 920327.21 | M9: 929891.19 | N9: 963431.15 | O9: 978326.69 | P9: 1005509.2 | Q9: 1005754.8 | R9: 997157.78 | S9: 992286.09 | T9: 1006098.5 | U9: 1029056.3 | V9: 1049372.1 | W9: 1062782.1 | X9: 1071373.8 | Y9: 1114962.5 | Z9: 1150864 | AA9: 1175105.9 | AB9: 1168795 | AC9: 1174735
A10: 8 | B10: 精穀・製粉 | C10: 79937.796 | D10: 115129.75 | E10: 154295.61 | F10: 179373.15 | G10: 199562.46 | H10: 214943.76 | I10: 237915.9 | J10: 250208.33 | K10: 278246.4 | L10: 292167.92 | M10: 298865.14 | N10: 311575.45 | O10: 333612.23 | P10: 334766.74 | Q10: 336673.14 | R10: 326145.42 | S10: 321054.58 | T10: 327056.62 | U10: 329921 | V10: 322527.33 | W10: 314148.95 | X10: 307633.58 | Y10: 309171.19 | Z10: 308217.7 | AA10: 310712.58 | AB10: 306752.63 | AC10: 317702.72
A11: 9 | B11: その他の食料品 | C11: 10333706 | D11: 9968048.3 | E11: 9681353.4 | F11: 9433753.9 | G11: 9250855.8 | H11: 9056707.6 | I11: 8952492.6 | J11: 8904782.2 | K11: 8900816.5 | L11: 8876335 | M11: 8933441.4 | N11: 9022889.8 | O11: 9234240.6 | P11: 9371045.4 | Q11: 9312451.5 | R11: 9265287.7 | S11: 9212028.1 | T11: 9343392.6 | U11: 9404347.5 | V11: 9384189.1 | W11: 9409828 | X11: 9394727.7 | Y11: 9630855.3 | Z11: 9931150.8 | AA11: 10221118 | AB11: 10335116 | AC11: 10342970
A12: 10 | B12: 飲料 | C12: 1395345.4 | D12: 1930387.7 | E12: 2356924.4 | F12: 2963083.6 | G12: 3554164.4 | H12: 3911619.2 | I12: 4220223.2 | J12: 4397395.5 | K12: 4571426.5 | L12: 4640791.6 | M12: 4625107.2 | N12: 4774329.4 | O12: 4826886.7 | P12: 4933223.5 | Q12: 4935755.1 | R12: 4873622.5 | S12: 4811249.3 | T12: 4898844.7 | U12: 4946046.5 | V12: 4853112.4 | W12: 4821318.8 | X12: 4766437.1 | Y12: 4710900.2 | Z12: 4741920.9 | AA12: 4710353.8 | AB12: 4759452 | AC12: 4603701.9
A13: 11 | B13: 飼料・有機質肥料 | C13: 314570.29 | D13: 354641.83 | E13: 404864.35 | F13: 436960.59 | G13: 485520.93 | H13: 520197.29 | I13: 548197.9 | J13: 543219.97 | K13: 531754.21 | L13: 522569.25 | M13: 504623.84 | N13: 488611.18 | O13: 460244.54 | P13: 440708.75 | Q13: 429677.41 | R13: 437309.3 | S13: 428982.63 | T13: 436932.72 | U13: 454475.33 | V13: 444243.42 | W13: 441905.12 | X13: 444393.69 | Y13: 445763.69 | Z13: 467007.83 | AA13: 484874.19 | AB13: 498771.83 | AC13: 527026.99
A14: 12 | B14: たばこ | C14: 1555283.2 | D14: 1528396.8 | E14: 1606056 | F14: 1565042.7 | G14: 1545696 | H14: 1554318.1 | I14: 1603876.9 | J14: 1761019.7 | K14: 1809077.8 | L14: 1810920.1 | M14: 1840972.9 | N14: 1925644.8 | O14: 1866316.1 | P14: 1879882.5 | Q14: 1917679 | R14: 1921769.8 | S14: 1943800.5 | T14: 1938901.8 | U14: 1890541.1 | V14: 1872462.7 | W14: 1881770.8 | X14: 1869862.2 | Y14: 1795636.6 | Z14: 1739598 | AA14: 1721245.9 | AB14: 1660689.9 | AC14: 1605970.7
... A101: 99 | B101: 会員制団体 | C101: 630576.01 | D101: 1114277 | E101: 1768318.2 | F101: 2280756.2 | G101: 2763277.9 | H101: 3355866 | I101: 3751098 | J101: 4015315.1 | K101: 4062012.1 | L101: 4373009.9 | M101: 4836547.3 | N101: 5206805.2 | O101: 5344184.7 | P101: 5418894.7 | Q101: 5758587.4 | R101: 5880201 | S101: 5878221.1 | T101: 5832443.1 | U101: 5728610.7 | V101: 5701582.8 | W101: 5743219.3 | X101: 5711955 | Y101: 5662932.5 | Z101: 5668782.5 | AA101: 5671158.2 | AB101: 5593991.5 | AC101: 5482187

Sheet 部門別名目資本コスト
A1: 部門別名目資本コスト (名目資本サービス価格*実質資本ストック、100万円)
A2: JIP部門分類 | C2: 1994 | D2: 1995 | E2: 1996 | F2: 1997 | G2: 1998 | H2: 1999 | I2: 2000 | J2: 2001 | K2: 2002 | L2: 2003 | M2: 2004 | N2: 2005 | O2: 2006 | P2: 2007 | Q2: 2008 | R2: 2009 | S2: 2010 | T2: 2011 | U2: 2012 | V2: 2013 | W2: 2014 | X2: 2015 | Y2: 2016 | Z2: 2017 | AA2: 2018 | AB2: 2019 | AC2: 2020
A3: 1 | B3: 農業 | C3: 4633057.3 | D3: 4402532.3 | E3: 4245167.5 | F3: 3974805.5 | G3: 3787847.7 | H3: 3764896.4 | I3: 3562486.1 | J3: 3271904.8 | K3: 3045253.8 | L3: 2835933.2 | M3: 2697051.5 | N3: 2572250.5 | O3: 2473158.9 | P3: 2356959.9 | Q3: 2263060.2 | R3: 2114930.1 | S3: 1955236 | T3: 1807584.3 | U3: 1688079.3 | V3: 1608232 | W3: 1561738.5 | X3: 1553435.2 | Y3: 1519683.8 | Z3: 1609018.3 | AA3: 1572086.2 | AB3: 1527812.4 | AC3: 1516681.6
A4: 2 | B4: 農業サービス | C4: 506913.35 | D4: 486539.84 | E4: 467161.13 | F4: 431648.79 | G4: 405557.57 | H4: 386549.63 | I4: 355590.47 | J4: 319309.24 | K4: 283649.35 | L4: 248802.35 | M4: 222482.97 | N4: 196381.76 | O4: 180525.65 | P4: 168259.57 | Q4: 157311.08 | R4: 144261.86 | S4: 131781.71 | T4: 121643.62 | U4: 113237.6 | V4: 109275.43 | W4: 102357.69 | X4: 99599.781 | Y4: 92893.764 | Z4: 88899.411 | AA4: 85452.502 | AB4: 79786.034 | AC4: 75658.472
A5: 3 | B5: 林業 | C5: 109143.33 | D5: 101323.2 | E5: 94149.516 | F5: 88497.586 | G5: 77666.3 | H5: 77790.102 | I5: 72308.544 | J5: 72502.287 | K5: 72510.344 | L5: 68119.047 | M5: 70164.851 | N5: 67293.979 | O5: 64947.439 | P5: 63492.715 | Q5: 60849.728 | R5: 57631.797 | S5: 54673.228 | T5: 51281.948 | U5: 48419.851 | V5: 46899.093 | W5: 43973.883 | X5: 43175.971 | Y5: 41264.341 | Z5: 41940.07 | AA5: 43553.102 | AB5: 41968.963 | AC5: 40385.02
A6: 4 | B6: 漁業 | C6: 605805.38 | D6: 601699.97 | E6: 594290.53 | F6: 569536.7 | G6: 517774.89 | H6: 472664.72 | I6: 465969.31 | J6: 451789.56 | K6: 421131.96 | L6: 373725.27 | M6: 365544.79 | N6: 344631.15 | O6: 329823.71 | P6: 307715.84 | Q6: 291604.19 | R6: 272298.99 | S6: 257280.88 | T6: 241047.62 | U6: 229008.25 | V6: 223585.65 | W6: 208990.62 | X6: 206660.57 | Y6: 199484.34 | Z6: 204093.62 | AA6: 212349.19 | AB6: 204176.06 | AC6: 194392.49
A7: 5 | B7: 鉱業 | C7: 410539.81 | D7: 385694.74 | E7: 365359.36 | F7: 331892.03 | G7: 302071.04 | H7: 292573.96 | I7: 285694.15 | J7: 262620.25 | K7: 252801.68 | L7: 227660.36 | M7: 219667.71 | N7: 201799.35 | O7: 202041.04 | P7: 201389.99 | Q7: 201677.05 | R7: 193179.84 | S7: 181031.21 | T7: 169177.72 | U7: 158774.99 | V7: 160214.46 | W7: 163201 | X7: 162161.71 | Y7: 153814.59 | Z7: 163276.89 | AA7: 155630.66 | AB7: 145314.57 | AC7: 139541.47
A8: 6 | B8: 畜産食料品 | C8: 288417.22 | D8: 294219.75 | E8: 301046.79 | F8: 292760.8 | G8: 289330.07 | H8: 305534.76 | I8: 314787.71 | J8: 321721.85 | K8: 325757.14 | L8: 314957.18 | M8: 321023.36 | N8: 318932.6 | O8: 343260.53 | P8: 354368.12 | Q8: 351375.2 | R8: 338029.04 | S8: 325324.72 | T8: 309843.19 | U8: 300221.16 | V8: 299381.78 | W8: 295357.01 | X8: 300148.45 | Y8: 306007.33 | Z8: 322785.23 | AA8: 327008.41 | AB8: 334694.62 | AC8: 339761.97
A9: 7 | B9: 水産食料品 | C9: 118554.71 | D9: 124791.53 | E9: 129067.48 | F9: 128405.06 | G9: 121530.14 | H9: 121715.17 | I9: 119181.26 | J9: 112931.41 | K9: 107565.5 | L9: 100700.95 | M9: 103363.51 | N9: 106798.44 | O9: 110374.62 | P9: 114802.23 | Q9: 114642.76 | R9: 109978.58 | S9: 105637.7 | T9: 102083.96 | U9: 100295.56 | V9: 100313.48 | W9: 99366.982 | X9: 98524.71 | Y9: 101341.31 | Z9: 106825.82 | AA9: 107124.51 | AB9: 104198.07 | AC9: 105448.3
A10: 8 | B10: 精穀・製粉 | C10: 12372.446 | D10: 19301.362 | E10: 27088.482 | F10: 30220.872 | G10: 32078.651 | H10: 34654.005 | I10: 37833.478 | J10: 38326.143 | K10: 42294.766 | L10: 42330.854 | M10: 42905.122 | N10: 44014.191 | O10: 48490.719 | P10: 48158.227 | Q10: 48408.246 | R10: 45238.488 | S10: 43087.69 | T10: 40693.122 | U10: 39508.855 | V10: 37650.057 | W10: 35357.233 | X10: 33522.205 | Y10: 33085.885 | Z10: 33072.315 | AA10: 32311.902 | AB10: 31244.467 | AC10: 32880.034
A11: 9 | B11: その他の食料品 | C11: 1654396.1 | D11: 1506473.2 | E11: 1423248 | F11: 1301481.8 | G11: 1198801.2 | H11: 1171282.2 | I11: 1134485.7 | J11: 1083626.6 | K11: 1058972.2 | L11: 1009167.8 | M11: 1030110.1 | N11: 1025031.5 | O11: 1081994.1 | P11: 1104660.2 | Q11: 1095763.1 | R11: 1061253.5 | S11: 1023349.7 | T11: 985167.2 | U11: 953375.79 | V11: 930941.55 | W11: 911692.64 | X11: 891850.57 | Y11: 901935.74 | Z11: 950316.44 | AA11: 963405.68 | AB11: 961388.61 | AC11: 967021.22
A12: 10 | B12: 飲料 | C12: 236271.63 | D12: 330510.84 | E12: 406132.18 | F12: 493637.45 | G12: 564221.81 | H12: 617521.58 | I12: 647415.93 | J12: 644080.49 | K12: 645459.59 | L12: 619292.27 | M12: 606624.1 | N12: 612289.62 | O12: 623954.97 | P12: 639966.36 | Q12: 639381.47 | R12: 611242.66 | S12: 583079.61 | T12: 562330.23 | U12: 542264.18 | V12: 516413.08 | W12: 500220.39 | X12: 483360.7 | Y12: 465115.75 | Z12: 473404.99 | AA12: 457828.57 | AB12: 458197.18 | AC12: 440351.33
A13: 11 | B13: 飼料・有機質肥料 | C13: 52723.77 | D13: 59626.236 | E13: 69439.939 | F13: 72537.747 | G13: 78632.494 | H13: 85427.704 | I13: 89333.451 | J13: 85104.97 | K13: 80977.674 | L13: 75898.573 | M13: 71712.143 | N13: 66670.99 | O13: 63551.099 | P13: 60814.345 | Q13: 59625.828 | R13: 59927.952 | S13: 57248.159 | T13: 54611.249 | U13: 54962.943 | V13: 52303.394 | W13: 50469.575 | X13: 49651.094 | Y13: 48761.295 | Z13: 51638.78 | AA13: 52351.559 | AB13: 53269.613 | AC13: 57272.637
A14: 12 | B14: たばこ | C14: 245041.05 | D14: 230099.99 | E14: 242783.8 | F14: 215700.21 | G14: 193969.75 | H14: 190444.91 | I14: 185779.92 | J14: 191562.56 | K14: 186419.75 | L14: 172107.91 | M14: 173249.96 | N14: 172229.21 | O14: 168759.23 | P14: 168581.04 | Q14: 173644.54 | R14: 172339.57 | S14: 174797.75 | T14: 168699.98 | U14: 158080.05 | V14: 155890.01 | W14: 155525.43 | X14: 152797.84 | Y14: 140804.11 | Z14: 137467.92 | AA14: 133634.95 | AB14: 124975.55 | AC14: 121691.48
... A101: 99 | B101: 会員制団体 | C101: 110761.03 | D101: 165680.22 | E101: 248696.08 | F101: 291651.31 | G101: 322013.85 | H101: 390181.25 | I101: 426671.36 | J101: 432643 | K101: 425223.46 | L101: 442263.4 | M101: 508866.43 | N101: 541403.7 | O101: 568101.87 | P101: 573227.29 | Q101: 599684.43 | R101: 600043.45 | S101: 587163.44 | T101: 576312.73 | U101: 553034.49 | V101: 539637.6 | W101: 534159.98 | X101: 521728.68 | Y101: 495124.15 | Z101: 499766.91 | AA101: 501067.96 | AB101: 488427.17 | AC101: 487619.67
B103: 合計 | C103: =SUM(C3:C101) -> 1.694601e+08 | D103: =SUM(D3:D101) -> 1.6955524e+08 | E103: =SUM(E3:E101) -> 1.7331495e+08 | F103: =SUM(F3:F101) -> 1.6669278e+08 | G103: =SUM(G3:G101) -> 1.6106679e+08 | H103: =SUM(H3:H101) -> 1.677889e+08 | I103: =SUM(I3:I101) -> 1.6584289e+08 | J103: =SUM(J3:J101) -> 1.5917521e+08 | ... AC103: =SUM(AC3:AC101) -> 1.1102095e+08
B104: 2015年=100 | C104: =C103/$X103*100 -> 139.42877 | D104: =D103/$X103*100 -> 139.50705 | E104: =E103/$X103*100 -> 142.60048 | F104: =F103/$X103*100 -> 137.15188 | G104: =G103/$X103*100 -> 132.52291 | H104: =H103/$X103*100 -> 138.05374 | I104: =I103/$X103*100 -> 136.4526 | J104: =J103/$X103*100 -> 130.96655 | ... AC104: =AC103/$X103*100 -> 91.346077

Sheet 資産別名目投資フロー
A1: 資産別名目投資フロー (100万円)
A2: JIP資本財分類 | C2: 1994 | D2: 1995 | E2: 1996 | F2: 1997 | G2: 1998 | H2: 1999 | I2: 2000 | J2: 2001 | K2: 2002 | L2: 2003 | M2: 2004 | N2: 2005 | O2: 2006 | P2: 2007 | Q2: 2008 | R2: 2009 | S2: 2010 | T2: 2011 | U2: 2012 | V2: 2013 | W2: 2014 | X2: 2015 | Y2: 2016 | Z2: 2017 | AA2: 2018 | AB2: 2019 | AC2: 2020
A3: 100 | B3: 1.住宅 | C3: 0 | D3: 30559800 | E3: 33870400 | F3: 31242000 | G3: 26555800 | H3: 26154100 | I3: 26254600 | J3: 25122200 | K3: 24125500 | L3: 23845100 | M3: 24503000 | N3: 24436200 | O3: 24790000 | P3: 22854300 | Q3: 21964700 | R3: 17797400 | S3: 17368600 | T3: 18503200 | U3: 18766500 | V3: 20760200 | W3: 20958300 | X3: 21105300 | Y3: 21794100 | Z3: 22128700 | AA3: 21050200 | AB3: 22092700 | AC3: 20585200
A4: 210 | B4: 2a.住宅以外の建物 | C4: 0 | D4: 19445900 | E4: 19972100 | F4: 19650500 | G4: 18880900 | H4: 18076700 | I4: 17912500 | J4: 16647100 | K4: 15525200 | L4: 15292800 | M4: 14719900 | N4: 15288500 | O4: 16172400 | P4: 15619900 | Q4: 15225500 | R4: 14252000 | S4: 13369500 | T4: 13929700 | U4: 14717700 | V4: 16273200 | W4: 16693100 | X4: 17579000 | Y4: 18464300 | Z4: 19389500 | AA4: 20019400 | AB4: 19545800 | AC4: 19030000
A5: 220 | B5: 2b.構築物 | C5: 0 | D5: 39193100 | E5: 39363700 | F5: 37238900 | G5: 37330900 | H5: 35340500 | I5: 33953300 | J5: 32197300 | K5: 29324600 | L5: 27157100 | M5: 25366600 | N5: 24396600 | O5: 22762600 | P5: 21395600 | Q5: 20629100 | R5: 20533800 | S5: 19916900 | T5: 20322000 | U5: 19197700 | V5: 20494000 | W5: 20647600 | X5: 20471800 | Y5: 21205500 | Z5: 21582200 | AA5: 22257900 | AB5: 23349300 | AC5: 24145000
A6: 230 | B6: 2c.土地改良 | C6: 0 | D6: 1630300 | E6: 1581300 | F6: 1546800 | G6: 1519300 | H6: 1497900 | I6: 1510500 | J6: 1445100 | K6: 1355800 | L6: 1130100 | M6: 1106600 | N6: 1192400 | O6: 1130400 | P6: 1049000 | Q6: 998700 | R6: 736300 | S6: 673400 | T6: 521100 | U6: 536600 | V6: 726200 | W6: 907900 | X6: 1174200 | Y6: 1236600 | Z6: 1054700 | AA6: 1138700 | AB6: 924500 | AC6: 871900
A7: 310 | B7: 3a.輸送用機械 | C7: 0 | D7: 7314800 | E7: 7225300 | F7: 7002200 | G7: 5630700 | H7: 5814400 | I7: 6137200 | J7: 6282500 | K7: 6298400 | L7: 6701000 | M7: 6792600 | N7: 7294500 | O7: 7291200 | P7: 7048400 | Q7: 6757300 | R7: 5538300 | S7: 6078700 | T7: 5622200 | U7: 6855500 | V7: 6916100 | W7: 7516100 | X7: 7786800 | Y7: 7563300 | Z7: 7863100 | AA7: 7933500 | AB7: 8064700 | AC7: 6832600
A8: 321 | B8: 3ba.情報機器 | C8: 0 | D8: 8208484.8 | E8: 8974088.7 | F8: 8641700.7 | G8: 7194689.9 | H8: 6824801.9 | I8: 6177669 | J8: 5573312.2 | K8: 4286106.1 | L8: 3621179.2 | M8: 3525829.2 | N8: 3315886.9 | O8: 3035790.3 | P8: 3491950.1 | Q8: 2998297 | R8: 2407344.2 | S8: 2512271.5 | T8: 2289426.6 | U8: 1778066.2 | V8: 1968030.2 | W8: 2389806.6 | X8: 2485635.5 | Y8: 1829174.3 | Z8: 2166419.7 | AA8: 2311225.5 | AB8: 2363756.1 | AC8: 2635419.1
A9: 322 | B9: 3bb.通信機器 | C9: 0 | D9: 3778415.2 | E9: 5125311.3 | F9: 5241899.3 | G9: 4640510.1 | H9: 4988898.1 | I9: 5655931 | J9: 4680587.8 | K9: 4379893.9 | L9: 4861420.8 | M9: 4704770.8 | N9: 4945813.1 | O9: 4856709.7 | P9: 4658549.9 | Q9: 4878503 | R9: 3864655.8 | S9: 4206828.5 | T9: 4230973.4 | U9: 4316833.8 | V9: 4383069.8 | W9: 4533093.4 | X9: 4352864.5 | Y9: 4557125.7 | Z9: 4490880.3 | AA9: 4480974.5 | AB9: 4869143.9 | AC9: 4832780.9
A10: 330 | B10: 3c.その他の機械・設備 | C10: 0 | D10: 29516800 | E10: 31428400 | F10: 32792400 | G10: 31060400 | H10: 29345100 | I10: 29421000 | J10: 28788700 | K10: 25272800 | L10: 24894700 | M10: 25806100 | N10: 28576200 | O10: 30036900 | P10: 30989700 | Q10: 29706500 | R10: 23746500 | S10: 22782500 | T10: 23577000 | U10: 25148100 | V10: 25066400 | W10: 26742400 | X10: 28443100 | Y10: 27519700 | Z10: 28743000 | AA10: 29827800 | AB10: 29697100 | AC10: 27764300
A11: 400 | B11: 4.防衛装備品 | C11: 0 | D11: 609300 | E11: 660200 | F11: 553800 | G11: 598100 | H11: 609400 | I11: 654400 | J11: 717800 | K11: 672100 | L11: 627900 | M11: 645200 | N11: 619400 | O11: 674100 | P11: 571900 | Q11: 667700 | R11: 649100 | S11: 558400 | T11: 553600 | U11: 589100 | V11: 502600 | W11: 623500 | X11: 747300 | Y11: 757100 | Z11: 915400 | AA11: 1135700 | AB11: 1044100 | AC11: 937800
A12: 500 | B12: 5.育成生物資源 | C12: 0 | D12: 205400 | E12: 201200 | F12: 192900 | G12: 184100 | H12: 176900 | I12: 193200 | J12: 196500 | K12: 191500 | L12: 183300 | M12: 181900 | N12: 195300 | O12: 199900 | P12: 197900 | Q12: 186100 | R12: 170700 | S12: 169100 | T12: 165900 | U12: 170900 | V12: 169100 | W12: 177400 | X12: 186800 | Y12: 206900 | Z12: 235200 | AA12: 250200 | AB12: 242700 | AC12: 235100
A13: 610 | B13: 6a.研究・開発 | C13: 0 | D13: 13766200 | E13: 14596900 | F13: 15285800 | G13: 15726200 | H13: 15463600 | I13: 15717500 | J13: 15882700 | K13: 15882900 | L13: 15977600 | M13: 16069800 | N13: 16817500 | O13: 17417400 | P13: 18097500 | Q13: 18212300 | R13: 16694800 | S13: 16301100 | T13: 16427100 | U13: 16437000 | V13: 16931400 | W13: 18029100 | X13: 18577700 | Y13: 18193700 | Z13: 18379400 | AA13: 19039200 | AB13: 18645400 | AC13: 18526700
A14: 620 | B14: 6b.鉱物探査・評価 | C14: 0 | D14: 12900 | E14: 13400 | F14: 13000 | G14: 9400 | H14: 10100 | I14: 6900 | J14: 5800 | K14: 5000 | L14: 2400 | M14: 4600 | N14: 3200 | O14: 3000 | P14: 4700 | Q14: 14500 | R14: 19200 | S14: 14900 | T14: 14500 | U14: 15600 | V14: 21000 | W14: 20400 | X14: 15100 | Y14: 19900 | Z14: 32000 | AA14: 34500 | AB14: 31700 | AC14: 25500
... A16: 640 | B16: 6d.娯楽作品原本 | C16: 0 | D16: 690900 | E16: 716300 | F16: 731200 | G16: 734600 | H16: 731700 | I16: 784100 | J16: 781300 | K16: 798000 | L16: 805700 | M16: 813400 | N16: 832300 | O16: 843600 | P16: 832100 | Q16: 836900 | R16: 820900 | S16: 834200 | T16: 819100 | U16: 814700 | V16: 802100 | W16: 856200 | X16: 851600 | Y16: 864200 | Z16: 825300 | AA16: 827600 | AB16: 850100 | AC16: 786500

Sheet 資産別実質投資フロー
A1: 資産別実質投資フロー (100万円、2015年価格)
A2: JIP資本財分類 | C2: 1994 | D2: 1995 | E2: 1996 | F2: 1997 | G2: 1998 | H2: 1999 | I2: 2000 | J2: 2001 | K2: 2002 | L2: 2003 | M2: 2004 | N2: 2005 | O2: 2006 | P2: 2007 | Q2: 2008 | R2: 2009 | S2: 2010 | T2: 2011 | U2: 2012 | V2: 2013 | W2: 2014 | X2: 2015 | Y2: 2016 | Z2: 2017 | AA2: 2018 | AB2: 2019 | AC2: 2020
A3: 100 | B3: 1.住宅 | C3: 0 | D3: 31977200 | E3: 35310400 | F3: 32044900 | G3: 27740600 | H3: 27678600 | I3: 27816100 | J3: 26912900 | K3: 26181500 | L3: 25946100 | M3: 26617300 | N3: 26473000 | O3: 26496800 | P3: 23968800 | Q3: 22461100 | R3: 18599600 | S3: 18325900 | T3: 19514700 | U3: 19935000 | V3: 21664600 | W3: 21160200 | X3: 21105300 | Y3: 21902600 | Z3: 21862700 | AA3: 20456100 | AB3: 21202100 | AC3: 19551500
A4: 210 | B4: 2a.住宅以外の建物 | C4: 0 | D4: 20973508 | E4: 21468693 | F4: 20926806 | G4: 20523191 | H4: 20021311 | I4: 19808521 | J4: 18632240 | K4: 17558200 | L4: 17283700 | M4: 16527412 | N4: 16939222 | O4: 17661909 | P4: 16802308 | Q4: 15855508 | R4: 15202693 | S4: 14345185 | T4: 14544513 | U4: 15403100 | V4: 16796900 | W4: 16824200 | X4: 17579000 | Y4: 18561300 | Z4: 19215504 | AA4: 19530800 | AB4: 18751000 | AC4: 18205100
A5: 220 | B5: 2b.構築物 | C5: 0 | D5: 42967310 | E5: 43051472 | F5: 40233816 | G5: 41050390 | H5: 39616300 | I5: 37946800 | J5: 36399187 | K5: 33601400 | L5: 31064386 | M5: 28771187 | N5: 27247077 | O5: 24983039 | P5: 23101892 | Q5: 21288003 | R5: 21744688 | S5: 21159819 | T5: 21417684 | U5: 20217100 | V5: 21342408 | W5: 20864298 | X5: 20471800 | Y5: 21345700 | Z5: 21375603 | AA5: 21653495 | AB5: 22299404 | AC5: 22889005
A6: 230 | B6: 2c.土地改良 | C6: 0 | D6: 1719900 | E6: 1658600 | F6: 1608000 | G6: 1608800 | H6: 1611400 | I6: 1614900 | J6: 1569100 | K6: 1491100 | L6: 1240000 | M6: 1204700 | N6: 1281300 | O6: 1197300 | P6: 1092300 | Q6: 1000800 | R6: 751500 | S6: 691600 | T6: 533400 | U6: 548300 | V6: 737500 | W6: 911300 | X6: 1174200 | Y6: 1243900 | Z6: 1049700 | AA6: 1119800 | AB6: 893900 | AC6: 843000
